Workbook

Sheet cálculo
A2: PALPITE | B2: OFICIAL | C2: Leo Picca | D2: Leo Raposo | E2: Serginho | F2: Biel | G2: Rafinha | H2: Ranieri | I2: Nanel | J2: Marcel | K2: Dan | L2: Celsinho | M2: Enrico | N2: Gui Giron | O2: Scarpa | P2: Victor | Q2: Faber | R2: Felippe Leite | S2: Muca | T2: Feijão | U2: Ivan | V2: Michel | W2: Deco | X2: ="Ptos "&C2 -> Ptos Leo Picca | Y2: ="Ptos "&D2 -> Ptos Leo Raposo | Z2: ="Ptos "&E2 -> Ptos Serginho | AA2: ="Ptos "&F2 -> Ptos Biel | AB2: ="Ptos "&G2 -> Ptos Rafinha | AC2: ="Ptos "&H2 -> Ptos Ranieri | AD2: ="Ptos "&I2 -> Ptos Nanel | AE2: ="Ptos "&J2 -> Ptos Marcel | ... AR2: ="Ptos "&W2 -> Ptos Deco
C3: =SUM(X6:X166) -> 83.1 | D3: =SUM(Y6:Y166) -> 95 | E3: =SUM(Z6:Z166) -> 102.6 | F3: =SUM(AA6:AA166) -> 93.55 | G3: =SUM(AB6:AB166) -> 95 | H3: =SUM(AC6:AC166) -> 91 | I3: =SUM(AD6:AD166) -> 92.5 | J3: =SUM(AE6:AE166) -> 93 | ... W3: =SUM(AR6:AR166) -> 86.75
A4: ='1a FASE'!A5 -> ARTILHEIRO | B4: ='1a FASE'!B5 | C4: ='1a FASE'!C5 -> Kylian Mbappé | D4: ='1a FASE'!D5 -> Mohamed Salah | E4: ='1a FASE'!E5 -> João Pedro | F4: ='1a FASE'!F5 -> Ekitike | G4: ='1a FASE'!G5 -> Raphinha | H4: ='1a FASE'!H5 -> Robert Lewandowski | ... W4: ='1a FASE'!W5 -> Kylian Mbappé | X4: =+IF(C4=$B116,Pesos!$L$4,0)*IF(COUNTIF($C116:$W116,C4)=1,2,1)+IF(C4=$B4,Pesos!$L$4,0)*IF(COUNTIF($C116:$W116,C4)=1,2,1) -> 0 | Y4: =+IF(D4=$B116,Pesos!$L$4,0)*IF(COUNTIF($C116:$W116,D4)=1,2,1)+IF(D4=$B4,Pesos!$L$4,0)*IF(COUNTIF($C116:$W116,D4)=1,2,1) -> 0 | Z4: =+IF(E4=$B116,Pesos!$L$4,0)*IF(COUNTIF($C116:$W116,E4)=1,2,1)+IF(E4=$B4,Pesos!$L$4,0)*IF(COUNTIF($C116:$W116,E4)=1,2,1) -> 0 | AA4: =+IF(F4=$B116,Pesos!$L$4,0)*IF(COUNTIF($C116:$W116,F4)=1,2,1)+IF(F4=$B4,Pesos!$L$4,0)*IF(COUNTIF($C116:$W116,F4)=1,2,1) -> 0 | AB4: =+IF(G4=$B116,Pesos!$L$4,0)*IF(COUNTIF($C116:$W116,G4)=1,2,1)+IF(G4=$B4,Pesos!$L$4,0)*IF(COUNTIF($C116:$W116,G4)=1,2,1) -> 0 | AC4: =+IF(H4=$B116,Pesos!$L$4,0)*IF(COUNTIF($C116:$W116,H4)=1,2,1)+IF(H4=$B4,Pesos!$L$4,0)*IF(COUNTIF($C116:$W116,H4)=1,2,1) -> 0 | AD4: =+IF(I4=$B116,Pesos!$L$4,0)*IF(COUNTIF($C116:$W116,I4)=1,2,1)+IF(I4=$B4,Pesos!$L$4,0)*IF(COUNTIF($C116:$W116,I4)=1,2,1) -> 0 | AE4: =+IF(J4=$B116,Pesos!$L$4,0)*IF(COUNTIF($C116:$W116,J4)=1,2,1)+IF(J4=$B4,Pesos!$L$4,0)*IF(COUNTIF($C116:$W116,J4)=1,2,1) -> 0 | ... AR4: =+IF(W4=$B116,Pesos!$L$4,0)*IF(COUNTIF($C116:$W116,W4)=1,2,1)+IF(W4=$B4,Pesos!$L$4,0)*IF(COUNTIF($C116:$W116,W4)=1,2,1) -> 0
A5: GARÇOM | B5: ='1a FASE'!B6 | C5: ='1a FASE'!C6 -> Phil Foden | D5: ='1a FASE'!D6 -> Mohamed Salah | E5: ='1a FASE'!E6 -> Lamine Yamal | F5: ='1a FASE'!F6 -> Raphinha | G5: ='1a FASE'!G6 -> Lamine Yamal | H5: ='1a FASE'!H6 -> Lamine Yamal | I5: ='1a FASE'!I6 -> Lamine Yamal | ... W5: ='1a FASE'!W6 -> Vinícius Jr. | X5: =+IF(C5=$B116,Pesos!$L$4,0)*IF(COUNTIF($C116:$W116,C5)=1,2,1)+IF(C5=$B5,Pesos!$L$4,0)*IF(COUNTIF($C116:$W116,C5)=1,2,1) -> 0 | Y5: =+IF(D5=$B116,Pesos!$L$4,0)*IF(COUNTIF($C116:$W116,D5)=1,2,1)+IF(D5=$B5,Pesos!$L$4,0)*IF(COUNTIF($C116:$W116,D5)=1,2,1) -> 0 | Z5: =+IF(E5=$B116,Pesos!$L$4,0)*IF(COUNTIF($C116:$W116,E5)=1,2,1)+IF(E5=$B5,Pesos!$L$4,0)*IF(COUNTIF($C116:$W116,E5)=1,2,1) -> 0 | AA5: =+IF(F5=$B116,Pesos!$L$4,0)*IF(COUNTIF($C116:$W116,F5)=1,2,1)+IF(F5=$B5,Pesos!$L$4,0)*IF(COUNTIF($C116:$W116,F5)=1,2,1) -> 0 | AB5: =+IF(G5=$B116,Pesos!$L$4,0)*IF(COUNTIF($C116:$W116,G5)=1,2,1)+IF(G5=$B5,Pesos!$L$4,0)*IF(COUNTIF($C116:$W116,G5)=1,2,1) -> 0 | AC5: =+IF(H5=$B116,Pesos!$L$4,0)*IF(COUNTIF($C116:$W116,H5)=1,2,1)+IF(H5=$B5,Pesos!$L$4,0)*IF(COUNTIF($C116:$W116,H5)=1,2,1) -> 0 | AD5: =+IF(I5=$B116,Pesos!$L$4,0)*IF(COUNTIF($C116:$W116,I5)=1,2,1)+IF(I5=$B5,Pesos!$L$4,0)*IF(COUNTIF($C116:$W116,I5)=1,2,1) -> 0 | AE5: =+IF(J5=$B116,Pesos!$L$4,0)*IF(COUNTIF($C116:$W116,J5)=1,2,1)+IF(J5=$B5,Pesos!$L$4,0)*IF(COUNTIF($C116:$W116,J5)=1,2,1) -> 0 | ... AR5: =+IF(W5=$B116,Pesos!$L$4,0)*IF(COUNTIF($C116:$W116,W5)=1,2,1)+IF(W5=$B5,Pesos!$L$4,0)*IF(COUNTIF($C116:$W116,W5)=1,2,1) -> 0
A6: ='1a FASE'!A7 -> TIME FAVORITO | B6: ='1a FASE'!B7 | C6: ='1a FASE'!C7 -> Real Madrid | D6: ='1a FASE'!D7 -> Barcelona | E6: ='1a FASE'!E7 -> Barcelona | F6: ='1a FASE'!F7 -> Liverpool | G6: ='1a FASE'!G7 -> Barcelona | H6: ='1a FASE'!H7 -> Barcelona | ... W6: ='1a FASE'!W7 -> Barcelona | X6: =IF(COUNTIF($B$151:$B$158,C6)=1,Pesos!$K$22,0) -> 0 | Y6: =IF(COUNTIF($B$151:$B$158,D6)=1,Pesos!$K$22,0) -> 2 | Z6: =IF(COUNTIF($B$151:$B$158,E6)=1,Pesos!$K$22,0) -> 2 | AA6: =IF(COUNTIF($B$151:$B$158,F6)=1,Pesos!$K$22,0) -> 2 | AB6: =IF(COUNTIF($B$151:$B$158,G6)=1,Pesos!$K$22,0) -> 2 | AC6: =IF(COUNTIF($B$151:$B$158,H6)=1,Pesos!$K$22,0) -> 2 | AD6: =IF(COUNTIF($B$151:$B$158,I6)=1,Pesos!$K$22,0) -> 2 | AE6: =IF(COUNTIF($B$151:$B$158,J6)=1,Pesos!$K$22,0) -> 0 | ... AR6: =IF(COUNTIF($B$151:$B$158,W6)=1,Pesos!$K$22,0) -> 2
A7: ='1a FASE'!A8 -> Machtday 1 | B7: ='1a FASE'!B8 -> Union Saint-Gilloise | C7: ='1a FASE'!C8 -> PSV Eindhoven | D7: ='1a FASE'!D8 -> PSV Eindhoven | E7: ='1a FASE'!E8 -> PSV Eindhoven | F7: ='1a FASE'!F8 -> PSV Eindhoven | G7: ='1a FASE'!G8 -> PSV Eindhoven | H7: ='1a FASE'!H8 -> PSV Eindhoven | ... W7: ='1a FASE'!W8 -> PSV Eindhoven | X7: =+IF(C7=$B7,Pesos!$L$3,0)*IF(COUNTIF($C7:$W7,C7)=1,2,1) -> 0 | Y7: =+IF(D7=$B7,Pesos!$L$3,0)*IF(COUNTIF($C7:$W7,D7)=1,2,1) -> 0 | Z7: =+IF(E7=$B7,Pesos!$L$3,0)*IF(COUNTIF($C7:$W7,E7)=1,2,1) -> 0 | AA7: =+IF(F7=$B7,Pesos!$L$3,0)*IF(COUNTIF($C7:$W7,F7)=1,2,1) -> 0 | AB7: =+IF(G7=$B7,Pesos!$L$3,0)*IF(COUNTIF($C7:$W7,G7)=1,2,1) -> 0 | AC7: =+IF(H7=$B7,Pesos!$L$3,0)*IF(COUNTIF($C7:$W7,H7)=1,2,1) -> 0 | AD7: =+IF(I7=$B7,Pesos!$L$3,0)*IF(COUNTIF($C7:$W7,I7)=1,2,1) -> 0 | AE7: =+IF(J7=$B7,Pesos!$L$3,0)*IF(COUNTIF($C7:$W7,J7)=1,2,1) -> 0 | ... AR7: =+IF(W7=$B7,Pesos!$L$3,0)*IF(COUNTIF($C7:$W7,W7)=1,2,1) -> 0
A8: ='1a FASE'!A9 -> Machtday 1 | B8: ='1a FASE'!B9 -> Arsenal | C8: ='1a FASE'!C9 -> Arsenal | D8: ='1a FASE'!D9 -> Arsenal | E8: ='1a FASE'!E9 -> Arsenal | F8: ='1a FASE'!F9 -> Arsenal | G8: ='1a FASE'!G9 -> Arsenal | H8: ='1a FASE'!H9 -> Arsenal | ... W8: ='1a FASE'!W9 -> Arsenal | X8: =+IF(C8=$B8,Pesos!$L$3,0)*IF(COUNTIF($C8:$W8,C8)=1,2,1) -> 0.85 | Y8: =+IF(D8=$B8,Pesos!$L$3,0)*IF(COUNTIF($C8:$W8,D8)=1,2,1) -> 0.85 | Z8: =+IF(E8=$B8,Pesos!$L$3,0)*IF(COUNTIF($C8:$W8,E8)=1,2,1) -> 0.85 | AA8: =+IF(F8=$B8,Pesos!$L$3,0)*IF(COUNTIF($C8:$W8,F8)=1,2,1) -> 0.85 | AB8: =+IF(G8=$B8,Pesos!$L$3,0)*IF(COUNTIF($C8:$W8,G8)=1,2,1) -> 0.85 | AC8: =+IF(H8=$B8,Pesos!$L$3,0)*IF(COUNTIF($C8:$W8,H8)=1,2,1) -> 0.85 | AD8: =+IF(I8=$B8,Pesos!$L$3,0)*IF(COUNTIF($C8:$W8,I8)=1,2,1) -> 0.85 | AE8: =+IF(J8=$B8,Pesos!$L$3,0)*IF(COUNTIF($C8:$W8,J8)=1,2,1) -> 0.85 | ... AR8: =+IF(W8=$B8,Pesos!$L$3,0)*IF(COUNTIF($C8:$W8,W8)=1,2,1) -> 0.85
A9: ='1a FASE'!A10 -> Machtday 1 | B9: ='1a FASE'!B10 -> Real Madrid | C9: ='1a FASE'!C10 -> Real Madrid | D9: ='1a FASE'!D10 -> Real Madrid | E9: ='1a FASE'!E10 -> Real Madrid | F9: ='1a FASE'!F10 -> Real Madrid | G9: ='1a FASE'!G10 -> Real Madrid | H9: ='1a FASE'!H10 -> Real Madrid | ... W9: ='1a FASE'!W10 -> Real Madrid | X9: =+IF(C9=$B9,Pesos!$L$3,0)*IF(COUNTIF($C9:$W9,C9)=1,2,1) -> 0.85 | Y9: =+IF(D9=$B9,Pesos!$L$3,0)*IF(COUNTIF($C9:$W9,D9)=1,2,1) -> 0.85 | Z9: =+IF(E9=$B9,Pesos!$L$3,0)*IF(COUNTIF($C9:$W9,E9)=1,2,1) -> 0.85 | AA9: =+IF(F9=$B9,Pesos!$L$3,0)*IF(COUNTIF($C9:$W9,F9)=1,2,1) -> 0.85 | AB9: =+IF(G9=$B9,Pesos!$L$3,0)*IF(COUNTIF($C9:$W9,G9)=1,2,1) -> 0.85 | AC9: =+IF(H9=$B9,Pesos!$L$3,0)*IF(COUNTIF($C9:$W9,H9)=1,2,1) -> 0.85 | AD9: =+IF(I9=$B9,Pesos!$L$3,0)*IF(COUNTIF($C9:$W9,I9)=1,2,1) -> 0.85 | AE9: =+IF(J9=$B9,Pesos!$L$3,0)*IF(COUNTIF($C9:$W9,J9)=1,2,1) -> 0.85 | ... AR9: =+IF(W9=$B9,Pesos!$L$3,0)*IF(COUNTIF($C9:$W9,W9)=1,2,1) -> 0.85
A10: ='1a FASE'!A11 -> Machtday 1 | B10: ='1a FASE'!B11 -> Qarabag | C10: ='1a FASE'!C11 -> Benfica | D10: ='1a FASE'!D11 -> Benfica | E10: ='1a FASE'!E11 -> Benfica | F10: ='1a FASE'!F11 -> Benfica | G10: ='1a FASE'!G11 -> Benfica | H10: ='1a FASE'!H11 -> Benfica | ... W10: ='1a FASE'!W11 -> Benfica | X10: =+IF(C10=$B10,Pesos!$L$3,0)*IF(COUNTIF($C10:$W10,C10)=1,2,1) -> 0 | Y10: =+IF(D10=$B10,Pesos!$L$3,0)*IF(COUNTIF($C10:$W10,D10)=1,2,1) -> 0 | Z10: =+IF(E10=$B10,Pesos!$L$3,0)*IF(COUNTIF($C10:$W10,E10)=1,2,1) -> 0 | AA10: =+IF(F10=$B10,Pesos!$L$3,0)*IF(COUNTIF($C10:$W10,F10)=1,2,1) -> 0 | AB10: =+IF(G10=$B10,Pesos!$L$3,0)*IF(COUNTIF($C10:$W10,G10)=1,2,1) -> 0 | AC10: =+IF(H10=$B10,Pesos!$L$3,0)*IF(COUNTIF($C10:$W10,H10)=1,2,1) -> 0 | AD10: =+IF(I10=$B10,Pesos!$L$3,0)*IF(COUNTIF($C10:$W10,I10)=1,2,1) -> 0 | AE10: =+IF(J10=$B10,Pesos!$L$3,0)*IF(COUNTIF($C10:$W10,J10)=1,2,1) -> 0 | ... AR10: =+IF(W10=$B10,Pesos!$L$3,0)*IF(COUNTIF($C10:$W10,W10)=1,2,1) -> 0
A11: ='1a FASE'!A12 -> Machtday 1 | B11: ='1a FASE'!B12 -> Empate | C11: ='1a FASE'!C12 -> Juventus | D11: ='1a FASE'!D12 -> Juventus | E11: ='1a FASE'!E12 -> Borussia Dortmund | F11: ='1a FASE'!F12 -> Juventus | G11: ='1a FASE'!G12 -> Juventus | H11: ='1a FASE'!H12 -> Juventus | ... W11: ='1a FASE'!W12 -> Empate | X11: =+IF(C11=$B11,Pesos!$L$3,0)*IF(COUNTIF($C11:$W11,C11)=1,2,1) -> 0 | Y11: =+IF(D11=$B11,Pesos!$L$3,0)*IF(COUNTIF($C11:$W11,D11)=1,2,1) -> 0 | Z11: =+IF(E11=$B11,Pesos!$L$3,0)*IF(COUNTIF($C11:$W11,E11)=1,2,1) -> 0 | AA11: =+IF(F11=$B11,Pesos!$L$3,0)*IF(COUNTIF($C11:$W11,F11)=1,2,1) -> 0 | AB11: =+IF(G11=$B11,Pesos!$L$3,0)*IF(COUNTIF($C11:$W11,G11)=1,2,1) -> 0 | AC11: =+IF(H11=$B11,Pesos!$L$3,0)*IF(COUNTIF($C11:$W11,H11)=1,2,1) -> 0 | AD11: =+IF(I11=$B11,Pesos!$L$3,0)*IF(COUNTIF($C11:$W11,I11)=1,2,1) -> 0 | AE11: =+IF(J11=$B11,Pesos!$L$3,0)*IF(COUNTIF($C11:$W11,J11)=1,2,1) -> 0 | ... AR11: =+IF(W11=$B11,Pesos!$L$3,0)*IF(COUNTIF($C11:$W11,W11)=1,2,1) -> 0.85
A12: ='1a FASE'!A13 -> Machtday 1 | B12: ='1a FASE'!B13 -> Tottenham | C12: ='1a FASE'!C13 -> Tottenham | D12: ='1a FASE'!D13 -> Tottenham | E12: ='1a FASE'!E13 -> Tottenham | F12: ='1a FASE'!F13 -> Tottenham | G12: ='1a FASE'!G13 -> Tottenham | H12: ='1a FASE'!H13 -> Tottenham | ... W12: ='1a FASE'!W13 -> Tottenham | X12: =+IF(C12=$B12,Pesos!$L$3,0)*IF(COUNTIF($C12:$W12,C12)=1,2,1) -> 0.85 | Y12: =+IF(D12=$B12,Pesos!$L$3,0)*IF(COUNTIF($C12:$W12,D12)=1,2,1) -> 0.85 | Z12: =+IF(E12=$B12,Pesos!$L$3,0)*IF(COUNTIF($C12:$W12,E12)=1,2,1) -> 0.85 | AA12: =+IF(F12=$B12,Pesos!$L$3,0)*IF(COUNTIF($C12:$W12,F12)=1,2,1) -> 0.85 | AB12: =+IF(G12=$B12,Pesos!$L$3,0)*IF(COUNTIF($C12:$W12,G12)=1,2,1) -> 0.85 | AC12: =+IF(H12=$B12,Pesos!$L$3,0)*IF(COUNTIF($C12:$W12,H12)=1,2,1) -> 0.85 | AD12: =+IF(I12=$B12,Pesos!$L$3,0)*IF(COUNTIF($C12:$W12,I12)=1,2,1) -> 0.85 | AE12: =+IF(J12=$B12,Pesos!$L$3,0)*IF(COUNTIF($C12:$W12,J12)=1,2,1) -> 0 | ... AR12: =+IF(W12=$B12,Pesos!$L$3,0)*IF(COUNTIF($C12:$W12,W12)=1,2,1) -> 0.85
A13: ='1a FASE'!A14 -> Machtday 1 | B13: ='1a FASE'!B14 -> Empate | C13: ='1a FASE'!C14 -> Olympiacos | D13: ='1a FASE'!D14 -> Olympiacos | E13: ='1a FASE'!E14 -> Olympiacos | F13: ='1a FASE'!F14 -> Olympiacos | G13: ='1a FASE'!G14 -> Olympiacos | H13: ='1a FASE'!H14 -> Olympiacos | ... W13: ='1a FASE'!W14 -> Olympiacos | X13: =+IF(C13=$B13,Pesos!$L$3,0)*IF(COUNTIF($C13:$W13,C13)=1,2,1) -> 0 | Y13: =+IF(D13=$B13,Pesos!$L$3,0)*IF(COUNTIF($C13:$W13,D13)=1,2,1) -> 0 | Z13: =+IF(E13=$B13,Pesos!$L$3,0)*IF(COUNTIF($C13:$W13,E13)=1,2,1) -> 0 | AA13: =+IF(F13=$B13,Pesos!$L$3,0)*IF(COUNTIF($C13:$W13,F13)=1,2,1) -> 0 | AB13: =+IF(G13=$B13,Pesos!$L$3,0)*IF(COUNTIF($C13:$W13,G13)=1,2,1) -> 0 | AC13: =+IF(H13=$B13,Pesos!$L$3,0)*IF(COUNTIF($C13:$W13,H13)=1,2,1) -> 0 | AD13: =+IF(I13=$B13,Pesos!$L$3,0)*IF(COUNTIF($C13:$W13,I13)=1,2,1) -> 0 | AE13: =+IF(J13=$B13,Pesos!$L$3,0)*IF(COUNTIF($C13:$W13,J13)=1,2,1) -> 0 | ... AR13: =+IF(W13=$B13,Pesos!$L$3,0)*IF(COUNTIF($C13:$W13,W13)=1,2,1) -> 0
A14: ='1a FASE'!A15 -> Machtday 1 | B14: ='1a FASE'!B15 -> Empate | C14: ='1a FASE'!C15 -> Slavia Praga | D14: ='1a FASE'!D15 -> Slavia Praga | E14: ='1a FASE'!E15 -> Empate | F14: ='1a FASE'!F15 -> Slavia Praga | G14: ='1a FASE'!G15 -> Empate | H14: ='1a FASE'!H15 -> Slavia Praga | ... W14: ='1a FASE'!W15 -> Slavia Praga | X14: =+IF(C14=$B14,Pesos!$L$3,0)*IF(COUNTIF($C14:$W14,C14)=1,2,1) -> 0 | Y14: =+IF(D14=$B14,Pesos!$L$3,0)*IF(COUNTIF($C14:$W14,D14)=1,2,1) -> 0 | Z14: =+IF(E14=$B14,Pesos!$L$3,0)*IF(COUNTIF($C14:$W14,E14)=1,2,1) -> 0.85 | AA14: =+IF(F14=$B14,Pesos!$L$3,0)*IF(COUNTIF($C14:$W14,F14)=1,2,1) -> 0 | AB14: =+IF(G14=$B14,Pesos!$L$3,0)*IF(COUNTIF($C14:$W14,G14)=1,2,1) -> 0.85 | AC14: =+IF(H14=$B14,Pesos!$L$3,0)*IF(COUNTIF($C14:$W14,H14)=1,2,1) -> 0 | AD14: =+IF(I14=$B14,Pesos!$L$3,0)*IF(COUNTIF($C14:$W14,I14)=1,2,1) -> 0 | AE14: =+IF(J14=$B14,Pesos!$L$3,0)*IF(COUNTIF($C14:$W14,J14)=1,2,1) -> 0 | ... AR14: =+IF(W14=$B14,Pesos!$L$3,0)*IF(COUNTIF($C14:$W14,W14)=1,2,1) -> 0
A15: ='1a FASE'!A16 -> Machtday 1 | B15: ='1a FASE'!B16 -> Paris Saint-Germain | C15: ='1a FASE'!C16 -> Paris Saint-Germain | D15: ='1a FASE'!D16 -> Paris Saint-Germain | E15: ='1a FASE'!E16 -> Paris Saint-Germain | F15: ='1a FASE'!F16 -> Paris Saint-Germain | G15: ='1a FASE'!G16 -> Paris Saint-Germain | H15: ='1a FASE'!H16 -> Paris Saint-Germain | ... W15: ='1a FASE'!W16 -> Paris Saint-Germain | X15: =+IF(C15=$B15,Pesos!$L$3,0)*IF(COUNTIF($C15:$W15,C15)=1,2,1) -> 0.85 | Y15: =+IF(D15=$B15,Pesos!$L$3,0)*IF(COUNTIF($C15:$W15,D15)=1,2,1) -> 0.85 | Z15: =+IF(E15=$B15,Pesos!$L$3,0)*IF(COUNTIF($C15:$W15,E15)=1,2,1) -> 0.85 | AA15: =+IF(F15=$B15,Pesos!$L$3,0)*IF(COUNTIF($C15:$W15,F15)=1,2,1) -> 0.85 | AB15: =+IF(G15=$B15,Pesos!$L$3,0)*IF(COUNTIF($C15:$W15,G15)=1,2,1) -> 0.85 | AC15: =+IF(H15=$B15,Pesos!$L$3,0)*IF(COUNTIF($C15:$W15,H15)=1,2,1) -> 0.85 | AD15: =+IF(I15=$B15,Pesos!$L$3,0)*IF(COUNTIF($C15:$W15,I15)=1,2,1) -> 0.85 | AE15: =+IF(J15=$B15,Pesos!$L$3,0)*IF(COUNTIF($C15:$W15,J15)=1,2,1) -> 0.85 | ... AR15: =+IF(W15=$B15,Pesos!$L$3,0)*IF(COUNTIF($C15:$W15,W15)=1,2,1) -> 0.85
A16: ='1a FASE'!A17 -> Machtday 1 | B16: ='1a FASE'!B17 -> Bayern de Munique | C16: ='1a FASE'!C17 -> Bayern de Munique | D16: ='1a FASE'!D17 -> Bayern de Munique | E16: ='1a FASE'!E17 -> Bayern de Munique | F16: ='1a FASE'!F17 -> Empate | G16: ='1a FASE'!G17 -> Bayern de Munique | H16: ='1a FASE'!H17 -> Bayern de Munique | ... W16: ='1a FASE'!W17 -> Bayern de Munique | X16: =+IF(C16=$B16,Pesos!$L$3,0)*IF(COUNTIF($C16:$W16,C16)=1,2,1) -> 0.85 | Y16: =+IF(D16=$B16,Pesos!$L$3,0)*IF(COUNTIF($C16:$W16,D16)=1,2,1) -> 0.85 | Z16: =+IF(E16=$B16,Pesos!$L$3,0)*IF(COUNTIF($C16:$W16,E16)=1,2,1) -> 0.85 | AA16: =+IF(F16=$B16,Pesos!$L$3,0)*IF(COUNTIF($C16:$W16,F16)=1,2,1) -> 0 | AB16: =+IF(G16=$B16,Pesos!$L$3,0)*IF(COUNTIF($C16:$W16,G16)=1,2,1) -> 0.85 | AC16: =+IF(H16=$B16,Pesos!$L$3,0)*IF(COUNTIF($C16:$W16,H16)=1,2,1) -> 0.85 | AD16: =+IF(I16=$B16,Pesos!$L$3,0)*IF(COUNTIF($C16:$W16,I16)=1,2,1) -> 0.85 | AE16: =+IF(J16=$B16,Pesos!$L$3,0)*IF(COUNTIF($C16:$W16,J16)=1,2,1) -> 0.85 | ... AR16: =+IF(W16=$B16,Pesos!$L$3,0)*IF(COUNTIF($C16:$W16,W16)=1,2,1) -> 0.85
A17: ='1a FASE'!A18 -> Machtday 1 | B17: ='1a FASE'!B18 -> Liverpool | C17: ='1a FASE'!C18 -> Liverpool | D17: ='1a FASE'!D18 -> Liverpool | E17: ='1a FASE'!E18 -> Liverpool | F17: ='1a FASE'!F18 -> Liverpool | G17: ='1a FASE'!G18 -> Liverpool | H17: ='1a FASE'!H18 -> Liverpool | ... W17: ='1a FASE'!W18 -> Liverpool | X17: =+IF(C17=$B17,Pesos!$L$3,0)*IF(COUNTIF($C17:$W17,C17)=1,2,1) -> 0.85 | Y17: =+IF(D17=$B17,Pesos!$L$3,0)*IF(COUNTIF($C17:$W17,D17)=1,2,1) -> 0.85 | Z17: =+IF(E17=$B17,Pesos!$L$3,0)*IF(COUNTIF($C17:$W17,E17)=1,2,1) -> 0.85 | AA17: =+IF(F17=$B17,Pesos!$L$3,0)*IF(COUNTIF($C17:$W17,F17)=1,2,1) -> 0.85 | AB17: =+IF(G17=$B17,Pesos!$L$3,0)*IF(COUNTIF($C17:$W17,G17)=1,2,1) -> 0.85 | AC17: =+IF(H17=$B17,Pesos!$L$3,0)*IF(COUNTIF($C17:$W17,H17)=1,2,1) -> 0.85 | AD17: =+IF(I17=$B17,Pesos!$L$3,0)*IF(COUNTIF($C17:$W17,I17)=1,2,1) -> 0.85 | AE17: =+IF(J17=$B17,Pesos!$L$3,0)*IF(COUNTIF($C17:$W17,J17)=1,2,1) -> 0.85 | ... AR17: =+IF(W17=$B17,Pesos!$L$3,0)*IF(COUNTIF($C17:$W17,W17)=1,2,1) -> 0.85
A18: ='1a FASE'!A19 -> Machtday 1 | B18: ='1a FASE'!B19 -> Internazionale | C18: ='1a FASE'!C19 -> Internazionale | D18: ='1a FASE'!D19 -> Empate | E18: ='1a FASE'!E19 -> Ajax | F18: ='1a FASE'!F19 -> Internazionale | G18: ='1a FASE'!G19 -> Empate | H18: ='1a FASE'!H19 -> Ajax | ... W18: ='1a FASE'!W19 -> Empate | X18: =+IF(C18=$B18,Pesos!$L$3,0)*IF(COUNTIF($C18:$W18,C18)=1,2,1) -> 0.85 | Y18: =+IF(D18=$B18,Pesos!$L$3,0)*IF(COUNTIF($C18:$W18,D18)=1,2,1) -> 0 | Z18: =+IF(E18=$B18,Pesos!$L$3,0)*IF(COUNTIF($C18:$W18,E18)=1,2,1) -> 0 | AA18: =+IF(F18=$B18,Pesos!$L$3,0)*IF(COUNTIF($C18:$W18,F18)=1,2,1) -> 0.85 | AB18: =+IF(G18=$B18,Pesos!$L$3,0)*IF(COUNTIF($C18:$W18,G18)=1,2,1) -> 0 | AC18: =+IF(H18=$B18,Pesos!$L$3,0)*IF(COUNTIF($C18:$W18,H18)=1,2,1) -> 0 | AD18: =+IF(I18=$B18,Pesos!$L$3,0)*IF(COUNTIF($C18:$W18,I18)=1,2,1) -> 0.85 | AE18: =+IF(J18=$B18,Pesos!$L$3,0)*IF(COUNTIF($C18:$W18,J18)=1,2,1) -> 0 | ... AR18: =+IF(W18=$B18,Pesos!$L$3,0)*IF(COUNTIF($C18:$W18,W18)=1,2,1) -> 0
... A62: ='1a FASE'!A63 -> Machtday 4 | B62: ='1a FASE'!B63 -> Arsenal | C62: ='1a FASE'!C63 -> Arsenal | D62: ='1a FASE'!D63 -> Arsenal | E62: ='1a FASE'!E63 -> Arsenal | F62: ='1a FASE'!F63 -> Arsenal | G62: ='1a FASE'!G63 -> Arsenal | H62: ='1a FASE'!H63 -> Arsenal | ... W62: ='1a FASE'!W63 -> Arsenal | X62: =+IF(C62=$B62,Pesos!$L$3,0)*IF(COUNTIF($C62:$W62,C62)=1,2,1) -> 0.85 | Y62: =+IF(D62=$B62,Pesos!$L$3,0)*IF(COUNTIF($C62:$W62,D62)=1,2,1) -> 0.85 | Z62: =+IF(E62=$B62,Pesos!$L$3,0)*IF(COUNTIF($C62:$W62,E62)=1,2,1) -> 0.85 | AA62: =+IF(F62=$B62,Pesos!$L$3,0)*IF(COUNTIF($C62:$W62,F62)=1,2,1) -> 0.85 | AB62: =+IF(G62=$B62,Pesos!$L$3,0)*IF(COUNTIF($C62:$W62,G62)=1,2,1) -> 0.85 | AC62: =+IF(H62=$B62,Pesos!$L$3,0)*IF(COUNTIF($C62:$W62,H62)=1,2,1) -> 0.85 | AD62: =+IF(I62=$B62,Pesos!$L$3,0)*IF(COUNTIF($C62:$W62,I62)=1,2,1) -> 0.85 | AE62: =+IF(J62=$B62,Pesos!$L$3,0)*IF(COUNTIF($C62:$W62,J62)=1,2,1) -> 0.85 | ... AR62: =+IF(W62=$B62,Pesos!$L$3,0)*IF(COUNTIF($C62:$W62,W62)=1,2,1) -> 0.85
A63: ='1a FASE'!A62 -> Machtday 4 | B63: ='1a FASE'!B64 -> Bayern de Munique | C63: ='1a FASE'!C64 -> Paris Saint-Germain | D63: ='1a FASE'!D64 -> Paris Saint-Germain | E63: ='1a FASE'!E64 -> Paris Saint-Germain | F63: ='1a FASE'!F64 -> Paris Saint-Germain | G63: ='1a FASE'!G64 -> Paris Saint-Germain | H63: ='1a FASE'!H64 -> Bayern de Munique | I63: ='1a FASE'!I64 -> Paris Saint-Germain | ... W63: ='1a FASE'!W64 -> Paris Saint-Germain | X63: =+IF(C63=$B63,Pesos!$L$3,0)*IF(COUNTIF($C63:$W63,C63)=1,2,1) -> 0 | Y63: =+IF(D63=$B63,Pesos!$L$3,0)*IF(COUNTIF($C63:$W63,D63)=1,2,1) -> 0 | Z63: =+IF(E63=$B63,Pesos!$L$3,0)*IF(COUNTIF($C63:$W63,E63)=1,2,1) -> 0 | AA63: =+IF(F63=$B63,Pesos!$L$3,0)*IF(COUNTIF($C63:$W63,F63)=1,2,1) -> 0 | AB63: =+IF(G63=$B63,Pesos!$L$3,0)*IF(COUNTIF($C63:$W63,G63)=1,2,1) -> 0 | AC63: =+IF(H63=$B63,Pesos!$L$3,0)*IF(COUNTIF($C63:$W63,H63)=1,2,1) -> 0.85 | AD63: =+IF(I63=$B63,Pesos!$L$3,0)*IF(COUNTIF($C63:$W63,I63)=1,2,1) -> 0 | AE63: =+IF(J63=$B63,Pesos!$L$3,0)*IF(COUNTIF($C63:$W63,J63)=1,2,1) -> 0 | ... AR63: =+IF(W63=$B63,Pesos!$L$3,0)*IF(COUNTIF($C63:$W63,W63)=1,2,1) -> 0
A64: ='1a FASE'!A63 -> Machtday 4 | B64: ='1a FASE'!B65 -> Liverpool | C64: ='1a FASE'!C65 -> Liverpool | D64: ='1a FASE'!D65 -> Liverpool | E64: ='1a FASE'!E65 -> Liverpool | F64: ='1a FASE'!F65 -> Empate | G64: ='1a FASE'!G65 -> Liverpool | H64: ='1a FASE'!H65 -> Real Madrid | I64: ='1a FASE'!I65 -> Liverpool | ... W64: ='1a FASE'!W65 -> Empate | X64: =+IF(C64=$B64,Pesos!$L$3,0)*IF(COUNTIF($C64:$W64,C64)=1,2,1) -> 0.85 | Y64: =+IF(D64=$B64,Pesos!$L$3,0)*IF(COUNTIF($C64:$W64,D64)=1,2,1) -> 0.85 | Z64: =+IF(E64=$B64,Pesos!$L$3,0)*IF(COUNTIF($C64:$W64,E64)=1,2,1) -> 0.85 | AA64: =+IF(F64=$B64,Pesos!$L$3,0)*IF(COUNTIF($C64:$W64,F64)=1,2,1) -> 0 | AB64: =+IF(G64=$B64,Pesos!$L$3,0)*IF(COUNTIF($C64:$W64,G64)=1,2,1) -> 0.85 | AC64: =+IF(H64=$B64,Pesos!$L$3,0)*IF(COUNTIF($C64:$W64,H64)=1,2,1) -> 0 | AD64: =+IF(I64=$B64,Pesos!$L$3,0)*IF(COUNTIF($C64:$W64,I64)=1,2,1) -> 0.85 | AE64: =+IF(J64=$B64,Pesos!$L$3,0)*IF(COUNTIF($C64:$W64,J64)=1,2,1) -> 0.85 | ... AR64: =+IF(W64=$B64,Pesos!$L$3,0)*IF(COUNTIF($C64:$W64,W64)=1,2,1) -> 0
A65: ='1a FASE'!A64 -> Machtday 4 | B65: ='1a FASE'!B66 -> Atlético de Madrid | C65: ='1a FASE'!C66 -> Atlético de Madrid | D65: ='1a FASE'!D66 -> Atlético de Madrid | E65: ='1a FASE'!E66 -> Atlético de Madrid | F65: ='1a FASE'!F66 -> Atlético de Madrid | G65: ='1a FASE'!G66 -> Atlético de Madrid | H65: ='1a FASE'!H66 -> Atlético de Madrid | I65: ='1a FASE'!I66 -> Atlético de Madrid | ... W65: ='1a FASE'!W66 -> Atlético de Madrid | X65: =+IF(C65=$B65,Pesos!$L$3,0)*IF(COUNTIF($C65:$W65,C65)=1,2,1) -> 0.85 | Y65: =+IF(D65=$B65,Pesos!$L$3,0)*IF(COUNTIF($C65:$W65,D65)=1,2,1) -> 0.85 | Z65: =+IF(E65=$B65,Pesos!$L$3,0)*IF(COUNTIF($C65:$W65,E65)=1,2,1) -> 0.85 | AA65: =+IF(F65=$B65,Pesos!$L$3,0)*IF(COUNTIF($C65:$W65,F65)=1,2,1) -> 0.85 | AB65: =+IF(G65=$B65,Pesos!$L$3,0)*IF(COUNTIF($C65:$W65,G65)=1,2,1) -> 0.85 | AC65: =+IF(H65=$B65,Pesos!$L$3,0)*IF(COUNTIF($C65:$W65,H65)=1,2,1) -> 0.85 | AD65: =+IF(I65=$B65,Pesos!$L$3,0)*IF(COUNTIF($C65:$W65,I65)=1,2,1) -> 0.85 | AE65: =+IF(J65=$B65,Pesos!$L$3,0)*IF(COUNTIF($C65:$W65,J65)=1,2,1) -> 0.85 | ... AR65: =+IF(W65=$B65,Pesos!$L$3,0)*IF(COUNTIF($C65:$W65,W65)=1,2,1) -> 0.85
A66: ='1a FASE'!A65 -> Machtday 4 | B66: ='1a FASE'!B67 -> Empate | C66: ='1a FASE'!C67 -> Juventus | D66: ='1a FASE'!D67 -> Juventus | E66: ='1a FASE'!E67 -> Juventus | F66: ='1a FASE'!F67 -> Juventus | G66: ='1a FASE'!G67 -> Juventus | H66: ='1a FASE'!H67 -> Juventus | I66: ='1a FASE'!I67 -> Juventus | ... W66: ='1a FASE'!W67 -> Juventus | X66: =+IF(C66=$B66,Pesos!$L$3,0)*IF(COUNTIF($C66:$W66,C66)=1,2,1) -> 0 | Y66: =+IF(D66=$B66,Pesos!$L$3,0)*IF(COUNTIF($C66:$W66,D66)=1,2,1) -> 0 | Z66: =+IF(E66=$B66,Pesos!$L$3,0)*IF(COUNTIF($C66:$W66,E66)=1,2,1) -> 0 | AA66: =+IF(F66=$B66,Pesos!$L$3,0)*IF(COUNTIF($C66:$W66,F66)=1,2,1) -> 0 | AB66: =+IF(G66=$B66,Pesos!$L$3,0)*IF(COUNTIF($C66:$W66,G66)=1,2,1) -> 0 | AC66: =+IF(H66=$B66,Pesos!$L$3,0)*IF(COUNTIF($C66:$W66,H66)=1,2,1) -> 0 | AD66: =+IF(I66=$B66,Pesos!$L$3,0)*IF(COUNTIF($C66:$W66,I66)=1,2,1) -> 0 | AE66: =+IF(J66=$B66,Pesos!$L$3,0)*IF(COUNTIF($C66:$W66,J66)=1,2,1) -> 0 | ... AR66: =+IF(W66=$B66,Pesos!$L$3,0)*IF(COUNTIF($C66:$W66,W66)=1,2,1) -> 0
A67: ='1a FASE'!A66 -> Machtday 4 | B67: ='1a FASE'!B68 -> Tottenham | C67: ='1a FASE'!C68 -> Tottenham | D67: ='1a FASE'!D68 -> Tottenham | E67: ='1a FASE'!E68 -> Tottenham | F67: ='1a FASE'!F68 -> Tottenham | G67: ='1a FASE'!G68 -> Tottenham | H67: ='1a FASE'!H68 -> Tottenham | I67: ='1a FASE'!I68 -> Tottenham | ... W67: ='1a FASE'!W68 -> Tottenham | X67: =+IF(C67=$B67,Pesos!$L$3,0)*IF(COUNTIF($C67:$W67,C67)=1,2,1) -> 0.85 | Y67: =+IF(D67=$B67,Pesos!$L$3,0)*IF(COUNTIF($C67:$W67,D67)=1,2,1) -> 0.85 | Z67: =+IF(E67=$B67,Pesos!$L$3,0)*IF(COUNTIF($C67:$W67,E67)=1,2,1) -> 0.85 | AA67: =+IF(F67=$B67,Pesos!$L$3,0)*IF(COUNTIF($C67:$W67,F67)=1,2,1) -> 0.85 | AB67: =+IF(G67=$B67,Pesos!$L$3,0)*IF(COUNTIF($C67:$W67,G67)=1,2,1) -> 0.85 | AC67: =+IF(H67=$B67,Pesos!$L$3,0)*IF(COUNTIF($C67:$W67,H67)=1,2,1) -> 0.85 | AD67: =+IF(I67=$B67,Pesos!$L$3,0)*IF(COUNTIF($C67:$W67,I67)=1,2,1) -> 0.85 | AE67: =+IF(J67=$B67,Pesos!$L$3,0)*IF(COUNTIF($C67:$W67,J67)=1,2,1) -> 0.85 | ... AR67: =+IF(W67=$B67,Pesos!$L$3,0)*IF(COUNTIF($C67:$W67,W67)=1,2,1) -> 0.85
A68: ='1a FASE'!A67 -> Machtday 4 | B68: ='1a FASE'!B69 -> Empate | C68: ='1a FASE'!C69 -> Empate | D68: ='1a FASE'!D69 -> Olympiacos | E68: ='1a FASE'!E69 -> Olympiacos | F68: ='1a FASE'!F69 -> PSV Eindhoven | G68: ='1a FASE'!G69 -> Empate | H68: ='1a FASE'!H69 -> Olympiacos | I68: ='1a FASE'!I69 -> PSV Eindhoven | ... W68: ='1a FASE'!W69 -> Empate | X68: =+IF(C68=$B68,Pesos!$L$3,0)*IF(COUNTIF($C68:$W68,C68)=1,2,1) -> 0.85 | Y68: =+IF(D68=$B68,Pesos!$L$3,0)*IF(COUNTIF($C68:$W68,D68)=1,2,1) -> 0 | Z68: =+IF(E68=$B68,Pesos!$L$3,0)*IF(COUNTIF($C68:$W68,E68)=1,2,1) -> 0 | AA68: =+IF(F68=$B68,Pesos!$L$3,0)*IF(COUNTIF($C68:$W68,F68)=1,2,1) -> 0 | AB68: =+IF(G68=$B68,Pesos!$L$3,0)*IF(COUNTIF($C68:$W68,G68)=1,2,1) -> 0.85 | AC68: =+IF(H68=$B68,Pesos!$L$3,0)*IF(COUNTIF($C68:$W68,H68)=1,2,1) -> 0 | AD68: =+IF(I68=$B68,Pesos!$L$3,0)*IF(COUNTIF($C68:$W68,I68)=1,2,1) -> 0 | AE68: =+IF(J68=$B68,Pesos!$L$3,0)*IF(COUNTIF($C68:$W68,J68)=1,2,1) -> 0 | ... AR68: =+IF(W68=$B68,Pesos!$L$3,0)*IF(COUNTIF($C68:$W68,W68)=1,2,1) -> 0.85
A69: ='1a FASE'!A68 -> Machtday 4 | B69: ='1a FASE'!B70 -> Monaco | C69: ='1a FASE'!C70 -> Empate | D69: ='1a FASE'!D70 -> Monaco | E69: ='1a FASE'!E70 -> Monaco | F69: ='1a FASE'!F70 -> Monaco | G69: ='1a FASE'!G70 -> Empate | H69: ='1a FASE'!H70 -> Monaco | I69: ='1a FASE'!I70 -> Monaco | ... W69: ='1a FASE'!W70 -> Monaco | X69: =+IF(C69=$B69,Pesos!$L$3,0)*IF(COUNTIF($C69:$W69,C69)=1,2,1) -> 0 | Y69: =+IF(D69=$B69,Pesos!$L$3,0)*IF(COUNTIF($C69:$W69,D69)=1,2,1) -> 0.85 | Z69: =+IF(E69=$B69,Pesos!$L$3,0)*IF(COUNTIF($C69:$W69,E69)=1,2,1) -> 0.85 | AA69: =+IF(F69=$B69,Pesos!$L$3,0)*IF(COUNTIF($C69:$W69,F69)=1,2,1) -> 0.85 | AB69: =+IF(G69=$B69,Pesos!$L$3,0)*IF(COUNTIF($C69:$W69,G69)=1,2,1) -> 0 | AC69: =+IF(H69=$B69,Pesos!$L$3,0)*IF(COUNTIF($C69:$W69,H69)=1,2,1) -> 0.85 | AD69: =+IF(I69=$B69,Pesos!$L$3,0)*IF(COUNTIF($C69:$W69,I69)=1,2,1) -> 0.85 | AE69: =+IF(J69=$B69,Pesos!$L$3,0)*IF(COUNTIF($C69:$W69,J69)=1,2,1) -> 0.85 | ... AR69: =+IF(W69=$B69,Pesos!$L$3,0)*IF(COUNTIF($C69:$W69,W69)=1,2,1) -> 0.85
A70: ='1a FASE'!A69 -> Machtday 4 | B70: ='1a FASE'!B71 -> Empate | C70: ='1a FASE'!C71 -> Chelsea | D70: ='1a FASE'!D71 -> Chelsea | E70: ='1a FASE'!E71 -> Chelsea | F70: ='1a FASE'!F71 -> Chelsea | G70: ='1a FASE'!G71 -> Chelsea | H70: ='1a FASE'!H71 -> Chelsea | I70: ='1a FASE'!I71 -> Chelsea | ... W70: ='1a FASE'!W71 -> Chelsea | X70: =+IF(C70=$B70,Pesos!$L$3,0)*IF(COUNTIF($C70:$W70,C70)=1,2,1) -> 0 | Y70: =+IF(D70=$B70,Pesos!$L$3,0)*IF(COUNTIF($C70:$W70,D70)=1,2,1) -> 0 | Z70: =+IF(E70=$B70,Pesos!$L$3,0)*IF(COUNTIF($C70:$W70,E70)=1,2,1) -> 0 | AA70: =+IF(F70=$B70,Pesos!$L$3,0)*IF(COUNTIF($C70:$W70,F70)=1,2,1) -> 0 | AB70: =+IF(G70=$B70,Pesos!$L$3,0)*IF(COUNTIF($C70:$W70,G70)=1,2,1) -> 0 | AC70: =+IF(H70=$B70,Pesos!$L$3,0)*IF(COUNTIF($C70:$W70,H70)=1,2,1) -> 0 | AD70: =+IF(I70=$B70,Pesos!$L$3,0)*IF(COUNTIF($C70:$W70,I70)=1,2,1) -> 0 | AE70: =+IF(J70=$B70,Pesos!$L$3,0)*IF(COUNTIF($C70:$W70,J70)=1,2,1) -> 0 | ... AR70: =+IF(W70=$B70,Pesos!$L$3,0)*IF(COUNTIF($C70:$W70,W70)=1,2,1) -> 0
A71: ='1a FASE'!A70 -> Machtday 4 | B71: ='1a FASE'!B72 -> Pafos | C71: ='1a FASE'!C72 -> Villarreal | D71: ='1a FASE'!D72 -> Villarreal | E71: ='1a FASE'!E72 -> Villarreal | F71: ='1a FASE'!F72 -> Villarreal | G71: ='1a FASE'!G72 -> Empate | H71: ='1a FASE'!H72 -> Villarreal | I71: ='1a FASE'!I72 -> Villarreal | ... W71: ='1a FASE'!W72 -> Villarreal | X71: =+IF(C71=$B71,Pesos!$L$3,0)*IF(COUNTIF($C71:$W71,C71)=1,2,1) -> 0 | Y71: =+IF(D71=$B71,Pesos!$L$3,0)*IF(COUNTIF($C71:$W71,D71)=1,2,1) -> 0 | Z71: =+IF(E71=$B71,Pesos!$L$3,0)*IF(COUNTIF($C71:$W71,E71)=1,2,1) -> 0 | AA71: =+IF(F71=$B71,Pesos!$L$3,0)*IF(COUNTIF($C71:$W71,F71)=1,2,1) -> 0 | AB71: =+IF(G71=$B71,Pesos!$L$3,0)*IF(COUNTIF($C71:$W71,G71)=1,2,1) -> 0 | AC71: =+IF(H71=$B71,Pesos!$L$3,0)*IF(COUNTIF($C71:$W71,H71)=1,2,1) -> 0 | AD71: =+IF(I71=$B71,Pesos!$L$3,0)*IF(COUNTIF($C71:$W71,I71)=1,2,1) -> 0 | AE71: =+IF(J71=$B71,Pesos!$L$3,0)*IF(COUNTIF($C71:$W71,J71)=1,2,1) -> 0 | ... AR71: =+IF(W71=$B71,Pesos!$L$3,0)*IF(COUNTIF($C71:$W71,W71)=1,2,1) -> 0
A72: ='1a FASE'!A71 -> Machtday 4 | B72: ='1a FASE'!B73 -> Manchester City | C72: ='1a FASE'!C73 -> Manchester City | D72: ='1a FASE'!D73 -> Manchester City | E72: ='1a FASE'!E73 -> Manchester City | F72: ='1a FASE'!F73 -> Manchester City | G72: ='1a FASE'!G73 -> Manchester City | H72: ='1a FASE'!H73 -> Borussia Dortmund | I72: ='1a FASE'!I73 -> Manchester City | ... W72: ='1a FASE'!W73 -> Manchester City | X72: =+IF(C72=$B72,Pesos!$L$3,0)*IF(COUNTIF($C72:$W72,C72)=1,2,1) -> 0.85 | Y72: =+IF(D72=$B72,Pesos!$L$3,0)*IF(COUNTIF($C72:$W72,D72)=1,2,1) -> 0.85 | Z72: =+IF(E72=$B72,Pesos!$L$3,0)*IF(COUNTIF($C72:$W72,E72)=1,2,1) -> 0.85 | AA72: =+IF(F72=$B72,Pesos!$L$3,0)*IF(COUNTIF($C72:$W72,F72)=1,2,1) -> 0.85 | AB72: =+IF(G72=$B72,Pesos!$L$3,0)*IF(COUNTIF($C72:$W72,G72)=1,2,1) -> 0.85 | AC72: =+IF(H72=$B72,Pesos!$L$3,0)*IF(COUNTIF($C72:$W72,H72)=1,2,1) -> 0 | AD72: =+IF(I72=$B72,Pesos!$L$3,0)*IF(COUNTIF($C72:$W72,I72)=1,2,1) -> 0.85 | AE72: =+IF(J72=$B72,Pesos!$L$3,0)*IF(COUNTIF($C72:$W72,J72)=1,2,1) -> 0.85 | ... AR72: =+IF(W72=$B72,Pesos!$L$3,0)*IF(COUNTIF($C72:$W72,W72)=1,2,1) -> 0.85
A73: ='1a FASE'!A72 -> Machtday 4 | B73: ='1a FASE'!B74 -> Internazionale | C73: ='1a FASE'!C74 -> Internazionale | D73: ='1a FASE'!D74 -> Internazionale | E73: ='1a FASE'!E74 -> Internazionale | F73: ='1a FASE'!F74 -> Internazionale | G73: ='1a FASE'!G74 -> Internazionale | H73: ='1a FASE'!H74 -> Internazionale | I73: ='1a FASE'!I74 -> Internazionale | ... W73: ='1a FASE'!W74 -> Internazionale | X73: =+IF(C73=$B73,Pesos!$L$3,0)*IF(COUNTIF($C73:$W73,C73)=1,2,1) -> 0.85 | Y73: =+IF(D73=$B73,Pesos!$L$3,0)*IF(COUNTIF($C73:$W73,D73)=1,2,1) -> 0.85 | Z73: =+IF(E73=$B73,Pesos!$L$3,0)*IF(COUNTIF($C73:$W73,E73)=1,2,1) -> 0.85 | AA73: =+IF(F73=$B73,Pesos!$L$3,0)*IF(COUNTIF($C73:$W73,F73)=1,2,1) -> 0.85 | AB73: =+IF(G73=$B73,Pesos!$L$3,0)*IF(COUNTIF($C73:$W73,G73)=1,2,1) -> 0.85 | AC73: =+IF(H73=$B73,Pesos!$L$3,0)*IF(COUNTIF($C73:$W73,H73)=1,2,1) -> 0.85 | AD73: =+IF(I73=$B73,Pesos!$L$3,0)*IF(COUNTIF($C73:$W73,I73)=1,2,1) -> 0.85 | AE73: =+IF(J73=$B73,Pesos!$L$3,0)*IF(COUNTIF($C73:$W73,J73)=1,2,1) -> 0.85 | ... AR73: =+IF(W73=$B73,Pesos!$L$3,0)*IF(COUNTIF($C73:$W73,W73)=1,2,1) -> 0.85
A74: ='1a FASE'!A73 -> Machtday 4 | B74: ='1a FASE'!B75 -> Bayer Leverkusen | C74: ='1a FASE'!C75 -> Benfica | D74: ='1a FASE'!D75 -> Empate | E74: ='1a FASE'!E75 -> Benfica | F74: ='1a FASE'!F75 -> Empate | G74: ='1a FASE'!G75 -> Benfica | H74: ='1a FASE'!H75 -> Benfica | I74: ='1a FASE'!I75 -> Benfica | ... W74: ='1a FASE'!W75 -> Empate | X74: =+IF(C74=$B74,Pesos!$L$3,0)*IF(COUNTIF($C74:$W74,C74)=1,2,1) -> 0 | Y74: =+IF(D74=$B74,Pesos!$L$3,0)*IF(COUNTIF($C74:$W74,D74)=1,2,1) -> 0 | Z74: =+IF(E74=$B74,Pesos!$L$3,0)*IF(COUNTIF($C74:$W74,E74)=1,2,1) -> 0 | AA74: =+IF(F74=$B74,Pesos!$L$3,0)*IF(COUNTIF($C74:$W74,F74)=1,2,1) -> 0 | AB74: =+IF(G74=$B74,Pesos!$L$3,0)*IF(COUNTIF($C74:$W74,G74)=1,2,1) -> 0 | AC74: =+IF(H74=$B74,Pesos!$L$3,0)*IF(COUNTIF($C74:$W74,H74)=1,2,1) -> 0 | AD74: =+IF(I74=$B74,Pesos!$L$3,0)*IF(COUNTIF($C74:$W74,I74)=1,2,1) -> 0 | AE74: =+IF(J74=$B74,Pesos!$L$3,0)*IF(COUNTIF($C74:$W74,J74)=1,2,1) -> 0 | ... AR74: =+IF(W74=$B74,Pesos!$L$3,0)*IF(COUNTIF($C74:$W74,W74)=1,2,1) -> 0
... A78: ='1a FASE'!A77 -> Machtday 4 | B78: ='1a FASE'!B79 -> Newcastle | C78: ='1a FASE'!C79 -> Newcastle | D78: ='1a FASE'!D79 -> Newcastle | E78: ='1a FASE'!E79 -> Newcastle | F78: ='1a FASE'!F79 -> Newcastle | G78: ='1a FASE'!G79 -> Newcastle | H78: ='1a FASE'!H79 -> Newcastle | I78: ='1a FASE'!I79 -> Newcastle | ... W78: ='1a FASE'!W79 -> Newcastle | X78: =+IF(C78=$B78,Pesos!$L$3,0)*IF(COUNTIF($C78:$W78,C78)=1,2,1) -> 0.85 | Y78: =+IF(D78=$B78,Pesos!$L$3,0)*IF(COUNTIF($C78:$W78,D78)=1,2,1) -> 0.85 | Z78: =+IF(E78=$B78,Pesos!$L$3,0)*IF(COUNTIF($C78:$W78,E78)=1,2,1) -> 0.85 | AA78: =+IF(F78=$B78,Pesos!$L$3,0)*IF(COUNTIF($C78:$W78,F78)=1,2,1) -> 0.85 | AB78: =+IF(G78=$B78,Pesos!$L$3,0)*IF(COUNTIF($C78:$W78,G78)=1,2,1) -> 0.85 | AC78: =+IF(H78=$B78,Pesos!$L$3,0)*IF(COUNTIF($C78:$W78,H78)=1,2,1) -> 0.85 | AD78: =+IF(I78=$B78,Pesos!$L$3,0)*IF(COUNTIF($C78:$W78,I78)=1,2,1) -> 0.85 | AE78: =+IF(J78=$B78,Pesos!$L$3,0)*IF(COUNTIF($C78:$W78,J78)=1,2,1) -> 0.85 | ... AR78: =+IF(W78=$B78,Pesos!$L$3,0)*IF(COUNTIF($C78:$W78,W78)=1,2,1) -> 0.85
A79: ='1a FASE'!A80 -> Machtday 5 | B79: ='1a FASE'!B80 -> Benfica | C79: ='1a FASE'!C80 -> Benfica | D79: ='1a FASE'!D80 -> Ajax | E79: ='1a FASE'!E80 -> Benfica | F79: ='1a FASE'!F80 -> Benfica | G79: ='1a FASE'!G80 -> Ajax | H79: ='1a FASE'!H80 -> Ajax | ... W79: ='1a FASE'!W80 -> Empate | X79: =+IF(C79=$B79,Pesos!$L$3,0)*IF(COUNTIF($C79:$W79,C79)=1,2,1) -> 0.85 | Y79: =+IF(D79=$B79,Pesos!$L$3,0)*IF(COUNTIF($C79:$W79,D79)=1,2,1) -> 0 | Z79: =+IF(E79=$B79,Pesos!$L$3,0)*IF(COUNTIF($C79:$W79,E79)=1,2,1) -> 0.85 | AA79: =+IF(F79=$B79,Pesos!$L$3,0)*IF(COUNTIF($C79:$W79,F79)=1,2,1) -> 0.85 | AB79: =+IF(G79=$B79,Pesos!$L$3,0)*IF(COUNTIF($C79:$W79,G79)=1,2,1) -> 0 | AC79: =+IF(H79=$B79,Pesos!$L$3,0)*IF(COUNTIF($C79:$W79,H79)=1,2,1) -> 0 | AD79: =+IF(I79=$B79,Pesos!$L$3,0)*IF(COUNTIF($C79:$W79,I79)=1,2,1) -> 0.85 | AE79: =+IF(J79=$B79,Pesos!$L$3,0)*IF(COUNTIF($C79:$W79,J79)=1,2,1) -> 0 | ... AR79: =+IF(W79=$B79,Pesos!$L$3,0)*IF(COUNTIF($C79:$W79,W79)=1,2,1) -> 0
A80: ='1a FASE'!A81 -> Machtday 5 | B80: ='1a FASE'!B81 -> Union Saint-Gilloise | C80: ='1a FASE'!C81 -> Galatasaray | D80: ='1a FASE'!D81 -> Galatasaray | E80: ='1a FASE'!E81 -> Galatasaray | F80: ='1a FASE'!F81 -> Galatasaray | G80: ='1a FASE'!G81 -> Galatasaray | H80: ='1a FASE'!H81 -> Galatasaray | ... W80: ='1a FASE'!W81 -> Galatasaray | X80: =+IF(C80=$B80,Pesos!$L$3,0)*IF(COUNTIF($C80:$W80,C80)=1,2,1) -> 0 | Y80: =+IF(D80=$B80,Pesos!$L$3,0)*IF(COUNTIF($C80:$W80,D80)=1,2,1) -> 0 | Z80: =+IF(E80=$B80,Pesos!$L$3,0)*IF(COUNTIF($C80:$W80,E80)=1,2,1) -> 0 | AA80: =+IF(F80=$B80,Pesos!$L$3,0)*IF(COUNTIF($C80:$W80,F80)=1,2,1) -> 0 | AB80: =+IF(G80=$B80,Pesos!$L$3,0)*IF(COUNTIF($C80:$W80,G80)=1,2,1) -> 0 | AC80: =+IF(H80=$B80,Pesos!$L$3,0)*IF(COUNTIF($C80:$W80,H80)=1,2,1) -> 0 | AD80: =+IF(I80=$B80,Pesos!$L$3,0)*IF(COUNTIF($C80:$W80,I80)=1,2,1) -> 0 | AE80: =+IF(J80=$B80,Pesos!$L$3,0)*IF(COUNTIF($C80:$W80,J80)=1,2,1) -> 0 | ... AR80: =+IF(W80=$B80,Pesos!$L$3,0)*IF(COUNTIF($C80:$W80,W80)=1,2,1) -> 0
A81: ='1a FASE'!A82 -> Machtday 5 | B81: ='1a FASE'!B82 -> Bayer Leverkusen | C81: ='1a FASE'!C82 -> Manchester City | D81: ='1a FASE'!D82 -> Manchester City | E81: ='1a FASE'!E82 -> Manchester City | F81: ='1a FASE'!F82 -> Manchester City | G81: ='1a FASE'!G82 -> Manchester City | H81: ='1a FASE'!H82 -> Manchester City | ... W81: ='1a FASE'!W82 -> Manchester City | X81: =+IF(C81=$B81,Pesos!$L$3,0)*IF(COUNTIF($C81:$W81,C81)=1,2,1) -> 0 | Y81: =+IF(D81=$B81,Pesos!$L$3,0)*IF(COUNTIF($C81:$W81,D81)=1,2,1) -> 0 | Z81: =+IF(E81=$B81,Pesos!$L$3,0)*IF(COUNTIF($C81:$W81,E81)=1,2,1) -> 0 | AA81: =+IF(F81=$B81,Pesos!$L$3,0)*IF(COUNTIF($C81:$W81,F81)=1,2,1) -> 0 | AB81: =+IF(G81=$B81,Pesos!$L$3,0)*IF(COUNTIF($C81:$W81,G81)=1,2,1) -> 0 | AC81: =+IF(H81=$B81,Pesos!$L$3,0)*IF(COUNTIF($C81:$W81,H81)=1,2,1) -> 0 | AD81: =+IF(I81=$B81,Pesos!$L$3,0)*IF(COUNTIF($C81:$W81,I81)=1,2,1) -> 0 | AE81: =+IF(J81=$B81,Pesos!$L$3,0)*IF(COUNTIF($C81:$W81,J81)=1,2,1) -> 0 | ... AR81: =+IF(W81=$B81,Pesos!$L$3,0)*IF(COUNTIF($C81:$W81,W81)=1,2,1) -> 0
A82: ='1a FASE'!A83 -> Machtday 5 | B82: ='1a FASE'!B83 -> Chelsea | C82: ='1a FASE'!C83 -> Empate | D82: ='1a FASE'!D83 -> Chelsea | E82: ='1a FASE'!E83 -> Empate | F82: ='1a FASE'!F83 -> Barcelona | G82: ='1a FASE'!G83 -> Chelsea | H82: ='1a FASE'!H83 -> Chelsea | ... W82: ='1a FASE'!W83 -> Empate | X82: =+IF(C82=$B82,Pesos!$L$3,0)*IF(COUNTIF($C82:$W82,C82)=1,2,1) -> 0 | Y82: =+IF(D82=$B82,Pesos!$L$3,0)*IF(COUNTIF($C82:$W82,D82)=1,2,1) -> 0.85 | Z82: =+IF(E82=$B82,Pesos!$L$3,0)*IF(COUNTIF($C82:$W82,E82)=1,2,1) -> 0 | AA82: =+IF(F82=$B82,Pesos!$L$3,0)*IF(COUNTIF($C82:$W82,F82)=1,2,1) -> 0 | AB82: =+IF(G82=$B82,Pesos!$L$3,0)*IF(COUNTIF($C82:$W82,G82)=1,2,1) -> 0.85 | AC82: =+IF(H82=$B82,Pesos!$L$3,0)*IF(COUNTIF($C82:$W82,H82)=1,2,1) -> 0.85 | AD82: =+IF(I82=$B82,Pesos!$L$3,0)*IF(COUNTIF($C82:$W82,I82)=1,2,1) -> 0.85 | AE82: =+IF(J82=$B82,Pesos!$L$3,0)*IF(COUNTIF($C82:$W82,J82)=1,2,1) -> 0.85 | ... AR82: =+IF(W82=$B82,Pesos!$L$3,0)*IF(COUNTIF($C82:$W82,W82)=1,2,1) -> 0
A83: ='1a FASE'!A84 -> Machtday 5 | B83: ='1a FASE'!B84 -> Borussia Dortmund | C83: ='1a FASE'!C84 -> Borussia Dortmund | D83: ='1a FASE'!D84 -> Borussia Dortmund | E83: ='1a FASE'!E84 -> Borussia Dortmund | F83: ='1a FASE'!F84 -> Borussia Dortmund | G83: ='1a FASE'!G84 -> Borussia Dortmund | H83: ='1a FASE'!H84 -> Borussia Dortmund | ... W83: ='1a FASE'!W84 -> Borussia Dortmund | X83: =+IF(C83=$B83,Pesos!$L$3,0)*IF(COUNTIF($C83:$W83,C83)=1,2,1) -> 0.85 | Y83: =+IF(D83=$B83,Pesos!$L$3,0)*IF(COUNTIF($C83:$W83,D83)=1,2,1) -> 0.85 | Z83: =+IF(E83=$B83,Pesos!$L$3,0)*IF(COUNTIF($C83:$W83,E83)=1,2,1) -> 0.85 | AA83: =+IF(F83=$B83,Pesos!$L$3,0)*IF(COUNTIF($C83:$W83,F83)=1,2,1) -> 0.85 | AB83: =+IF(G83=$B83,Pesos!$L$3,0)*IF(COUNTIF($C83:$W83,G83)=1,2,1) -> 0.85 | AC83: =+IF(H83=$B83,Pesos!$L$3,0)*IF(COUNTIF($C83:$W83,H83)=1,2,1) -> 0.85 | AD83: =+IF(I83=$B83,Pesos!$L$3,0)*IF(COUNTIF($C83:$W83,I83)=1,2,1) -> 0.85 | AE83: =+IF(J83=$B83,Pesos!$L$3,0)*IF(COUNTIF($C83:$W83,J83)=1,2,1) -> 0.85 | ... AR83: =+IF(W83=$B83,Pesos!$L$3,0)*IF(COUNTIF($C83:$W83,W83)=1,2,1) -> 0.85
A84: ='1a FASE'!A85 -> Machtday 5 | B84: ='1a FASE'!B85 -> Napoli | C84: ='1a FASE'!C85 -> Napoli | D84: ='1a FASE'!D85 -> Napoli | E84: ='1a FASE'!E85 -> Napoli | F84: ='1a FASE'!F85 -> Napoli | G84: ='1a FASE'!G85 -> Napoli | H84: ='1a FASE'!H85 -> Napoli | ... W84: ='1a FASE'!W85 -> Napoli | X84: =+IF(C84=$B84,Pesos!$L$3,0)*IF(COUNTIF($C84:$W84,C84)=1,2,1) -> 0.85 | Y84: =+IF(D84=$B84,Pesos!$L$3,0)*IF(COUNTIF($C84:$W84,D84)=1,2,1) -> 0.85 | Z84: =+IF(E84=$B84,Pesos!$L$3,0)*IF(COUNTIF($C84:$W84,E84)=1,2,1) -> 0.85 | AA84: =+IF(F84=$B84,Pesos!$L$3,0)*IF(COUNTIF($C84:$W84,F84)=1,2,1) -> 0.85 | AB84: =+IF(G84=$B84,Pesos!$L$3,0)*IF(COUNTIF($C84:$W84,G84)=1,2,1) -> 0.85 | AC84: =+IF(H84=$B84,Pesos!$L$3,0)*IF(COUNTIF($C84:$W84,H84)=1,2,1) -> 0.85 | AD84: =+IF(I84=$B84,Pesos!$L$3,0)*IF(COUNTIF($C84:$W84,I84)=1,2,1) -> 0.85 | AE84: =+IF(J84=$B84,Pesos!$L$3,0)*IF(COUNTIF($C84:$W84,J84)=1,2,1) -> 0.85 | ... AR84: =+IF(W84=$B84,Pesos!$L$3,0)*IF(COUNTIF($C84:$W84,W84)=1,2,1) -> 0.85
A85: ='1a FASE'!A86 -> Machtday 5 | B85: ='1a FASE'!B86 -> Empate | C85: ='1a FASE'!C86 -> Empate | D85: ='1a FASE'!D86 -> Athletic Bilbao | E85: ='1a FASE'!E86 -> Athletic Bilbao | F85: ='1a FASE'!F86 -> Athletic Bilbao | G85: ='1a FASE'!G86 -> Athletic Bilbao | H85: ='1a FASE'!H86 -> Slavia Praga | ... W85: ='1a FASE'!W86 -> Athletic Bilbao | X85: =+IF(C85=$B85,Pesos!$L$3,0)*IF(COUNTIF($C85:$W85,C85)=1,2,1) -> 0.85 | Y85: =+IF(D85=$B85,Pesos!$L$3,0)*IF(COUNTIF($C85:$W85,D85)=1,2,1) -> 0 | Z85: =+IF(E85=$B85,Pesos!$L$3,0)*IF(COUNTIF($C85:$W85,E85)=1,2,1) -> 0 | AA85: =+IF(F85=$B85,Pesos!$L$3,0)*IF(COUNTIF($C85:$W85,F85)=1,2,1) -> 0 | AB85: =+IF(G85=$B85,Pesos!$L$3,0)*IF(COUNTIF($C85:$W85,G85)=1,2,1) -> 0 | AC85: =+IF(H85=$B85,Pesos!$L$3,0)*IF(COUNTIF($C85:$W85,H85)=1,2,1) -> 0 | AD85: =+IF(I85=$B85,Pesos!$L$3,0)*IF(COUNTIF($C85:$W85,I85)=1,2,1) -> 0 | AE85: =+IF(J85=$B85,Pesos!$L$3,0)*IF(COUNTIF($C85:$W85,J85)=1,2,1) -> 0 | ... AR85: =+IF(W85=$B85,Pesos!$L$3,0)*IF(COUNTIF($C85:$W85,W85)=1,2,1) -> 0
A86: ='1a FASE'!A87 -> Machtday 5 | B86: ='1a FASE'!B87 -> Juventus | C86: ='1a FASE'!C87 -> Juventus | D86: ='1a FASE'!D87 -> Juventus | E86: ='1a FASE'!E87 -> Juventus | F86: ='1a FASE'!F87 -> Juventus | G86: ='1a FASE'!G87 -> Juventus | H86: ='1a FASE'!H87 -> Juventus | ... W86: ='1a FASE'!W87 -> Juventus | X86: =+IF(C86=$B86,Pesos!$L$3,0)*IF(COUNTIF($C86:$W86,C86)=1,2,1) -> 0.85 | Y86: =+IF(D86=$B86,Pesos!$L$3,0)*IF(COUNTIF($C86:$W86,D86)=1,2,1) -> 0.85 | Z86: =+IF(E86=$B86,Pesos!$L$3,0)*IF(COUNTIF($C86:$W86,E86)=1,2,1) -> 0.85 | AA86: =+IF(F86=$B86,Pesos!$L$3,0)*IF(COUNTIF($C86:$W86,F86)=1,2,1) -> 0.85 | AB86: =+IF(G86=$B86,Pesos!$L$3,0)*IF(COUNTIF($C86:$W86,G86)=1,2,1) -> 0.85 | AC86: =+IF(H86=$B86,Pesos!$L$3,0)*IF(COUNTIF($C86:$W86,H86)=1,2,1) -> 0.85 | AD86: =+IF(I86=$B86,Pesos!$L$3,0)*IF(COUNTIF($C86:$W86,I86)=1,2,1) -> 0.85 | AE86: =+IF(J86=$B86,Pesos!$L$3,0)*IF(COUNTIF($C86:$W86,J86)=1,2,1) -> 0.85 | ... AR86: =+IF(W86=$B86,Pesos!$L$3,0)*IF(COUNTIF($C86:$W86,W86)=1,2,1) -> 0.85
A87: ='1a FASE'!A88 -> Machtday 5 | B87: ='1a FASE'!B88 -> Olympique de Marselha | C87: ='1a FASE'!C88 -> Newcastle | D87: ='1a FASE'!D88 -> Olympique de Marselha | E87: ='1a FASE'!E88 -> Newcastle | F87: ='1a FASE'!F88 -> Olympique de Marselha | G87: ='1a FASE'!G88 -> Empate | H87: ='1a FASE'!H88 -> Newcastle | ... W87: ='1a FASE'!W88 -> Newcastle | X87: =+IF(C87=$B87,Pesos!$L$3,0)*IF(COUNTIF($C87:$W87,C87)=1,2,1) -> 0 | Y87: =+IF(D87=$B87,Pesos!$L$3,0)*IF(COUNTIF($C87:$W87,D87)=1,2,1) -> 0.85 | Z87: =+IF(E87=$B87,Pesos!$L$3,0)*IF(COUNTIF($C87:$W87,E87)=1,2,1) -> 0 | AA87: =+IF(F87=$B87,Pesos!$L$3,0)*IF(COUNTIF($C87:$W87,F87)=1,2,1) -> 0.85 | AB87: =+IF(G87=$B87,Pesos!$L$3,0)*IF(COUNTIF($C87:$W87,G87)=1,2,1) -> 0 | AC87: =+IF(H87=$B87,Pesos!$L$3,0)*IF(COUNTIF($C87:$W87,H87)=1,2,1) -> 0 | AD87: =+IF(I87=$B87,Pesos!$L$3,0)*IF(COUNTIF($C87:$W87,I87)=1,2,1) -> 0.85 | AE87: =+IF(J87=$B87,Pesos!$L$3,0)*IF(COUNTIF($C87:$W87,J87)=1,2,1) -> 0 | ... AR87: =+IF(W87=$B87,Pesos!$L$3,0)*IF(COUNTIF($C87:$W87,W87)=1,2,1) -> 0
...

Sheet 1a FASE
C1: =COUNTIF(AH5:AH117,1) -> 1 | D1: =COUNTIF(AA5:AA119,1) -> 1 | E1: =COUNTIF(AF5:AF119,1) -> 2 | F1: =COUNTIF(AE5:AE119,1) -> 3 | G1: =COUNTIF(AD5:AD119,1) -> 1 | H1: =COUNTIF(AN5:AN119,1) -> 2 | I1: =COUNTIF(AK5:AK119,1) -> 1 | J1: =COUNTIF(X5:X119,1) -> 1 | K1: =COUNTIF(Y5:Y119,1) -> 2 | L1: =COUNTIF(AM5:AM119,1) -> 1 | M1: =COUNTIF(AJ5:AJ119,1) -> 3 | N1: =COUNTIF(AB5:AB119,1) -> 0 | O1: =COUNTIF(AC5:AC119,1) -> 9 | P1: =COUNTIF(AI5:AI119,1) -> 1 | Q1: =COUNTIF(AL5:AL119,1) -> 6 | R1: =COUNTIF(Z5:Z119,1) -> 1 | S1: =COUNTIF(AG5:AG119,1) -> 1 | T1: =COUNTIF(AO5:AO119,1) -> 9 | U1: =COUNTIF(AP5:AP119,1) -> 4 | V1: =COUNTIF(AQ5:AQ119,1) -> 7 | W1: =COUNTIF(AR5:AR119,1) -> 0
A2: PALPITE | B2: OFICIAL | C2: Leo Picca | D2: Leo Raposo | E2: Serginho | F2: Biel | G2: Rafinha | H2: Ranieri | I2: Nanel | J2: Marcel | K2: Dan | L2: Celsinho | M2: Enrico | N2: Gui Giron | O2: Scarpa | P2: Victor | Q2: Faber | R2: Felippe Leite | S2: Muca | T2: Feijão | U2: Ivan | V2: Michel | W2: Deco | X2: Marcel | Y2: Dan | Z2: Felippe Leite | AA2: Leo Raposo | AB2: Gui Giron | AC2: Scarpa | AD2: Rafinha | AE2: Biel | AF2: Serginho | AG2: Muca | AH2: Leo Picca | AI2: Victor | AJ2: Enrico | AK2: Nanel | AL2: Faber | AM2: Celsinho | AN2: Ranieri | AO2: Feijão | AP2: Ivan | AQ2: Michel | AR2: Deco
A3: A PONTUAÇÃO | B3: ----- | C3: =HLOOKUP('1a FASE'!$C$2,'cálculo'!$C$2:$AR$3,2,FALSE) -> 83.1 | D3: =HLOOKUP('1a FASE'!$D$2,'cálculo'!$C$2:$AR$3,2,FALSE) -> 95 | E3: =HLOOKUP('1a FASE'!$E$2,'cálculo'!$C$2:$AR$3,2,FALSE) -> 102.6 | F3: =HLOOKUP('1a FASE'!$F$2,'cálculo'!$C$2:$AR$3,2,FALSE) -> 93.55 | G3: =HLOOKUP('1a FASE'!$G$2,'cálculo'!$C$2:$AR$3,2,FALSE) -> 95 | H3: =HLOOKUP('1a FASE'!$H$2,'cálculo'!$C$2:$AR$3,2,FALSE) -> 91 | I3: =HLOOKUP('1a FASE'!$I$2,'cálculo'!$C$2:$AR$3,2,FALSE) -> 92.5 | J3: =HLOOKUP('1a FASE'!$J$2,'cálculo'!$C$2:$AR$3,2,FALSE) -> 93 | K3: =HLOOKUP('1a FASE'!$K$2,'cálculo'!$C$2:$AR$3,2,FALSE) -> 91.85 | L3: =HLOOKUP('1a FASE'!$L$2,'cálculo'!$C$2:$AR$3,2,FALSE) -> 90.15 | M3: =HLOOKUP('1a FASE'!$M$2,'cálculo'!$C$2:$AR$3,2,FALSE) -> 90.15 | N3: =HLOOKUP('1a FASE'!$N$2,'cálculo'!$C$2:$AR$3,2,FALSE) -> 103.7 | O3: =HLOOKUP('1a FASE'!$O$2,'cálculo'!$C$2:$AR$3,2,FALSE) -> 91.8 | P3: =HLOOKUP('1a FASE'!$P$2,'cálculo'!$C$2:$AR$3,2,FALSE) -> 100.65 | Q3: =HLOOKUP('1a FASE'!$Q$2,'cálculo'!$C$2:$AR$3,2,FALSE) -> 96.65 | R3: =HLOOKUP('1a FASE'!$R$2,'cálculo'!$C$2:$AR$3,2,FALSE) -> 106.9 | S3: =HLOOKUP('1a FASE'!$S$2,'cálculo'!$C$2:$AR$3,2,FALSE) -> 91.6 | T3: =HLOOKUP('1a FASE'!$T$2,'cálculo'!$C$2:$AR$3,2,FALSE) -> 88.5 | U3: =HLOOKUP('1a FASE'!$U$2,'cálculo'!$C$2:$AR$3,2,FALSE) -> 81.7 | V3: =HLOOKUP('1a FASE'!$V$2,'cálculo'!$C$2:$AR$3,2,FALSE) -> 91.85 | W3: =HLOOKUP('1a FASE'!$W$2,'cálculo'!$C$2:$AR$3,2,FALSE) -> 86.75
A4: RANKING | B4: ----- | C4: =RANK(C3,$C$3:$W$3) -> 20 | D4: =RANK(D3,$C$3:$W$3) -> 6 | E4: =RANK(E3,$C$3:$W$3) -> 3 | F4: =RANK(F3,$C$3:$W$3) -> 8 | G4: =RANK(G3,$C$3:$W$3) -> 6 | H4: =RANK(H3,$C$3:$W$3) -> 15 | I4: =RANK(I3,$C$3:$W$3) -> 10 | J4: =RANK(J3,$C$3:$W$3) -> 9 | ... W4: =RANK(W3,$C$3:$W$3) -> 19
A5: ARTILHEIRO | C5: =VLOOKUP($C$2,Form_PrimeiraFase!$C$2:$FB$70,154,FALSE) -> Kylian Mbappé | D5: =VLOOKUP($D$2,Form_PrimeiraFase!$C$2:$FB$69,154,FALSE) -> Mohamed Salah | E5: =VLOOKUP($E$2,Form_PrimeiraFase!$C$2:$FB$69,154,FALSE) -> João Pedro | F5: =VLOOKUP($F$2,Form_PrimeiraFase!$C$2:$FB$69,154,FALSE) -> Ekitike | G5: =VLOOKUP($G$2,Form_PrimeiraFase!$C$2:$FB$69,154,FALSE) -> Raphinha | H5: =VLOOKUP($H$2,Form_PrimeiraFase!$C$2:$FB$69,154,FALSE) -> Robert Lewandowski | I5: =VLOOKUP($I$2,Form_PrimeiraFase!$C$2:$FB$69,154,FALSE) -> Harry Kane | J5: =VLOOKUP($J$2,Form_PrimeiraFase!$C$2:$FB$69,154,FALSE) -> Erling Haaland | K5: =VLOOKUP($K$2,Form_PrimeiraFase!$C$2:$FB$69,154,FALSE) -> Raphinha | L5: =VLOOKUP($L$2,Form_PrimeiraFase!$C$2:$FB$69,154,FALSE) -> Raphinha | M5: =VLOOKUP($M$2,Form_PrimeiraFase!$C$2:$FB$69,154,FALSE) -> Erling Haaland | N5: =VLOOKUP($N$2,Form_PrimeiraFase!$C$2:$FB$69,154,FALSE) -> Robert Lewandowski | O5: =VLOOKUP($O$2,Form_PrimeiraFase!$C$2:$FB$69,154,FALSE) -> Robert Lewandowski | P5: =VLOOKUP($P$2,Form_PrimeiraFase!$C$2:$FB$69,154,FALSE) -> Robert Lewandowski | Q5: =VLOOKUP($Q$2,Form_PrimeiraFase!$C$2:$FB$69,154,FALSE) -> Kylian Mbappé | R5: =VLOOKUP($R$2,Form_PrimeiraFase!$C$2:$FB$69,154,FALSE) -> Erling Haaland | S5: =VLOOKUP($S$2,Form_PrimeiraFase!$C$2:$FB$69,154,FALSE) -> Erling Haaland | T5: =VLOOKUP($T$2,Form_PrimeiraFase!$C$2:$FB$69,154,FALSE) -> Ousmane Dembélé | U5: =VLOOKUP($U$2,Form_PrimeiraFase!$C$2:$FB$69,154,FALSE) -> Raphinha | V5: =VLOOKUP($V$2,Form_PrimeiraFase!$C$2:$FB$69,154,FALSE) -> Harry Kane | W5: =VLOOKUP($W$2,Form_PrimeiraFase!$C$2:$FB$69,154,FALSE) -> Kylian Mbappé | X5: =COUNTIF($C5:$W5,J5) -> 4 | Y5: =COUNTIF($C5:$W5,K5) -> 4 | Z5: =COUNTIF($C5:$W5,R5) -> 4 | AA5: =COUNTIF($C5:$W5,D5) -> 1 | AB5: =COUNTIF($C5:$W5,N5) -> 4 | AC5: =COUNTIF($C5:$W5,O5) -> 4 | AD5: =COUNTIF($C5:$W5,G5) -> 4 | AE5: =COUNTIF($C5:$W5,F5) -> 1 | AF5: =COUNTIF($C5:$W5,E5) -> 1 | AG5: =COUNTIF($C5:$W5,S5) -> 4 | AH5: =COUNTIF($C5:$W5,C5) -> 3 | AI5: =COUNTIF($C5:$W5,P5) -> 4 | AJ5: =COUNTIF($C5:$W5,M5) -> 4 | AK5: =COUNTIF($C5:$W5,I5) -> 2 | AL5: =COUNTIF($C5:$W5,Q5) -> 3 | AM5: =COUNTIF($C5:$W5,L5) -> 4 | AN5: =COUNTIF($C5:$W5,H5) -> 4 | AO5: =COUNTIF($C5:$W5,T5) -> 1 | AP5: =COUNTIF($C5:$W5,U5) -> 4 | AQ5: =COUNTIF($C5:$W5,V5) -> 2 | AR5: =COUNTIF($C5:$W5,W5) -> 3
A6: GARÇOM | C6: =VLOOKUP($C$2,Form_PrimeiraFase!$C$2:$FB$69,155,FALSE) -> Phil Foden | D6: =VLOOKUP($D$2,Form_PrimeiraFase!$C$2:$FB$69,155,FALSE) -> Mohamed Salah | E6: =VLOOKUP($E$2,Form_PrimeiraFase!$C$2:$FB$69,155,FALSE) -> Lamine Yamal | F6: =VLOOKUP($F$2,Form_PrimeiraFase!$C$2:$FB$69,155,FALSE) -> Raphinha | G6: =VLOOKUP($G$2,Form_PrimeiraFase!$C$2:$FB$69,155,FALSE) -> Lamine Yamal | H6: =VLOOKUP($H$2,Form_PrimeiraFase!$C$2:$FB$69,155,FALSE) -> Lamine Yamal | I6: =VLOOKUP($I$2,Form_PrimeiraFase!$C$2:$FB$69,155,FALSE) -> Lamine Yamal | J6: =VLOOKUP($J$2,Form_PrimeiraFase!$C$2:$FB$69,155,FALSE) -> Désiré Doué | K6: =VLOOKUP($K$2,Form_PrimeiraFase!$C$2:$FB$69,155,FALSE) -> Lamine Yamal | L6: =VLOOKUP($L$2,Form_PrimeiraFase!$C$2:$FB$69,155,FALSE) -> Cole Palmer | M6: =VLOOKUP($M$2,Form_PrimeiraFase!$C$2:$FB$69,155,FALSE) -> Ousmane Dembélé | N6: =VLOOKUP($N$2,Form_PrimeiraFase!$C$2:$FB$69,155,FALSE) -> Cole Palmer | O6: =VLOOKUP($O$2,Form_PrimeiraFase!$C$2:$FB$69,155,FALSE) -> Eberechi Eze | P6: =VLOOKUP($P$2,Form_PrimeiraFase!$C$2:$FB$69,155,FALSE) -> Lamine Yamal | Q6: =VLOOKUP($Q$2,Form_PrimeiraFase!$C$2:$FB$69,155,FALSE) -> Raphinha | R6: =VLOOKUP($R$2,Form_PrimeiraFase!$C$2:$FB$69,155,FALSE) -> Vitinha | S6: =VLOOKUP($S$2,Form_PrimeiraFase!$C$2:$FB$69,155,FALSE) -> Mohamed Salah | T6: =VLOOKUP($T$2,Form_PrimeiraFase!$C$2:$FB$69,155,FALSE) -> Raphinha | U6: =VLOOKUP($U$2,Form_PrimeiraFase!$C$2:$FB$69,155,FALSE) -> Lamine Yamal | V6: =VLOOKUP($V$2,Form_PrimeiraFase!$C$2:$FB$69,155,FALSE) -> Vinícius Jr. | W6: =VLOOKUP($W$2,Form_PrimeiraFase!$C$2:$FB$69,155,FALSE) -> Vinícius Jr. | X6: =COUNTIF($C6:$W6,J6) -> 1 | Y6: =COUNTIF($C6:$W6,K6) -> 7 | Z6: =COUNTIF($C6:$W6,R6) -> 1 | AA6: =COUNTIF($C6:$W6,D6) -> 2 | AB6: =COUNTIF($C6:$W6,N6) -> 2 | AC6: =COUNTIF($C6:$W6,O6) -> 1 | AD6: =COUNTIF($C6:$W6,G6) -> 7 | AE6: =COUNTIF($C6:$W6,F6) -> 3 | AF6: =COUNTIF($C6:$W6,E6) -> 7 | AG6: =COUNTIF($C6:$W6,S6) -> 2 | AH6: =COUNTIF($C6:$W6,C6) -> 1 | AI6: =COUNTIF($C6:$W6,P6) -> 7 | AJ6: =COUNTIF($C6:$W6,M6) -> 1 | AK6: =COUNTIF($C6:$W6,I6) -> 7 | AL6: =COUNTIF($C6:$W6,Q6) -> 3 | AM6: =COUNTIF($C6:$W6,L6) -> 2 | AN6: =COUNTIF($C6:$W6,H6) -> 7 | AO6: =COUNTIF($C6:$W6,T6) -> 3 | AP6: =COUNTIF($C6:$W6,U6) -> 7 | AQ6: =COUNTIF($C6:$W6,V6) -> 2 | AR6: =COUNTIF($C6:$W6,W6) -> 2
A7: TIME FAVORITO | C7: =VLOOKUP($C$2,Form_PrimeiraFase!$C$2:$FB$69,156,FALSE) -> Real Madrid | D7: =VLOOKUP($D$2,Form_PrimeiraFase!$C$2:$FB$69,156,FALSE) -> Barcelona | E7: =VLOOKUP($E$2,Form_PrimeiraFase!$C$2:$FB$69,156,FALSE) -> Barcelona | F7: =VLOOKUP($F$2,Form_PrimeiraFase!$C$2:$FB$69,156,FALSE) -> Liverpool | G7: =VLOOKUP($G$2,Form_PrimeiraFase!$C$2:$FB$69,156,FALSE) -> Barcelona | H7: =VLOOKUP($H$2,Form_PrimeiraFase!$C$2:$FB$69,156,FALSE) -> Barcelona | I7: =VLOOKUP($I$2,Form_PrimeiraFase!$C$2:$FB$69,156,FALSE) -> Chelsea | J7: =VLOOKUP($J$2,Form_PrimeiraFase!$C$2:$FB$69,156,FALSE) -> Paris Saint-Germain | K7: =VLOOKUP($K$2,Form_PrimeiraFase!$C$2:$FB$69,156,FALSE) -> Liverpool | L7: =VLOOKUP($L$2,Form_PrimeiraFase!$C$2:$FB$69,156,FALSE) -> Barcelona | M7: =VLOOKUP($M$2,Form_PrimeiraFase!$C$2:$FB$69,156,FALSE) -> Liverpool | N7: =VLOOKUP($N$2,Form_PrimeiraFase!$C$2:$FB$69,156,FALSE) -> Barcelona | O7: =VLOOKUP($O$2,Form_PrimeiraFase!$C$2:$FB$69,156,FALSE) -> Barcelona | P7: =VLOOKUP($P$2,Form_PrimeiraFase!$C$2:$FB$69,156,FALSE) -> Barcelona | Q7: =VLOOKUP($Q$2,Form_PrimeiraFase!$C$2:$FB$69,156,FALSE) -> Barcelona | R7: =VLOOKUP($R$2,Form_PrimeiraFase!$C$2:$FB$69,156,FALSE) -> Real Madrid | S7: =VLOOKUP($S$2,Form_PrimeiraFase!$C$2:$FB$69,156,FALSE) -> Barcelona | T7: =VLOOKUP($T$2,Form_PrimeiraFase!$C$2:$FB$69,156,FALSE) -> Paris Saint-Germain | U7: =VLOOKUP($U$2,Form_PrimeiraFase!$C$2:$FB$69,156,FALSE) -> Barcelona | V7: =VLOOKUP($V$2,Form_PrimeiraFase!$C$2:$FB$69,156,FALSE) -> Liverpool | W7: =VLOOKUP($W$2,Form_PrimeiraFase!$C$2:$FB$69,156,FALSE) -> Barcelona | X7: =COUNTIF($C7:$W7,J7) -> 2 | Y7: =COUNTIF($C7:$W7,K7) -> 4 | Z7: =COUNTIF($C7:$W7,R7) -> 2 | AA7: =COUNTIF($C7:$W7,D7) -> 12 | AB7: =COUNTIF($C7:$W7,N7) -> 12 | AC7: =COUNTIF($C7:$W7,O7) -> 12 | AD7: =COUNTIF($C7:$W7,G7) -> 12 | AE7: =COUNTIF($C7:$W7,F7) -> 4 | AF7: =COUNTIF($C7:$W7,E7) -> 12 | AG7: =COUNTIF($C7:$W7,S7) -> 12 | AH7: =COUNTIF($C7:$W7,C7) -> 2 | AI7: =COUNTIF($C7:$W7,P7) -> 12 | AJ7: =COUNTIF($C7:$W7,M7) -> 4 | AK7: =COUNTIF($C7:$W7,I7) -> 1 | AL7: =COUNTIF($C7:$W7,Q7) -> 12 | AM7: =COUNTIF($C7:$W7,L7) -> 12 | AN7: =COUNTIF($C7:$W7,H7) -> 12 | AO7: =COUNTIF($C7:$W7,T7) -> 2 | AP7: =COUNTIF($C7:$W7,U7) -> 12 | AQ7: =COUNTIF($C7:$W7,V7) -> 4 | AR7: =COUNTIF($C7:$W7,W7) -> 12
A8: Machtday 1 | B8: Union Saint-Gilloise | C8: =VLOOKUP($C$2,Form_PrimeiraFase!$C$2:$FB$69,2,FALSE) -> PSV Eindhoven | D8: =VLOOKUP($D$2,Form_PrimeiraFase!$C$2:$FB$69,2,FALSE) -> PSV Eindhoven | E8: =VLOOKUP($E$2,Form_PrimeiraFase!$C$2:$FB$69,2,FALSE) -> PSV Eindhoven | F8: =VLOOKUP($F$2,Form_PrimeiraFase!$C$2:$FB$69,2,FALSE) -> PSV Eindhoven | G8: =VLOOKUP($G$2,Form_PrimeiraFase!$C$2:$FB$69,2,FALSE) -> PSV Eindhoven | H8: =VLOOKUP($H$2,Form_PrimeiraFase!$C$2:$FB$69,2,FALSE) -> PSV Eindhoven | I8: =VLOOKUP($I$2,Form_PrimeiraFase!$C$2:$FB$69,2,FALSE) -> PSV Eindhoven | J8: =VLOOKUP($J$2,Form_PrimeiraFase!$C$2:$FB$69,2,FALSE) -> PSV Eindhoven | K8: =VLOOKUP($K$2,Form_PrimeiraFase!$C$2:$FB$69,2,FALSE) -> PSV Eindhoven | L8: =VLOOKUP($L$2,Form_PrimeiraFase!$C$2:$FB$69,2,FALSE) -> PSV Eindhoven | M8: =VLOOKUP($M$2,Form_PrimeiraFase!$C$2:$FB$69,2,FALSE) -> PSV Eindhoven | N8: =VLOOKUP($N$2,Form_PrimeiraFase!$C$2:$FB$69,2,FALSE) -> PSV Eindhoven | O8: =VLOOKUP($O$2,Form_PrimeiraFase!$C$2:$FB$69,2,FALSE) -> PSV Eindhoven | P8: =VLOOKUP($P$2,Form_PrimeiraFase!$C$2:$FB$69,2,FALSE) -> PSV Eindhoven | Q8: =VLOOKUP($Q$2,Form_PrimeiraFase!$C$2:$FB$69,2,FALSE) -> PSV Eindhoven | R8: =VLOOKUP($R$2,Form_PrimeiraFase!$C$2:$FB$69,2,FALSE) -> PSV Eindhoven | S8: =VLOOKUP($S$2,Form_PrimeiraFase!$C$2:$FB$69,2,FALSE) -> PSV Eindhoven | T8: =VLOOKUP($T$2,Form_PrimeiraFase!$C$2:$FB$69,2,FALSE) -> PSV Eindhoven | U8: =VLOOKUP($U$2,Form_PrimeiraFase!$C$2:$FB$69,2,FALSE) -> Empate | V8: =VLOOKUP($V$2,Form_PrimeiraFase!$C$2:$FB$69,2,FALSE) -> PSV Eindhoven | W8: =VLOOKUP($W$2,Form_PrimeiraFase!$C$2:$FB$69,2,FALSE) -> PSV Eindhoven | X8: =COUNTIF($C8:$W8,J8) -> 20 | Y8: =COUNTIF($C8:$W8,K8) -> 20 | Z8: =COUNTIF($C8:$W8,R8) -> 20 | AA8: =COUNTIF($C8:$W8,D8) -> 20 | AB8: =COUNTIF($C8:$W8,N8) -> 20 | AC8: =COUNTIF($C8:$W8,O8) -> 20 | AD8: =COUNTIF($C8:$W8,G8) -> 20 | AE8: =COUNTIF($C8:$W8,F8) -> 20 | AF8: =COUNTIF($C8:$W8,E8) -> 20 | AG8: =COUNTIF($C8:$W8,S8) -> 20 | AH8: =COUNTIF($C8:$W8,C8) -> 20 | AI8: =COUNTIF($C8:$W8,P8) -> 20 | AJ8: =COUNTIF($C8:$W8,M8) -> 20 | AK8: =COUNTIF($C8:$W8,I8) -> 20 | AL8: =COUNTIF($C8:$W8,Q8) -> 20 | AM8: =COUNTIF($C8:$W8,L8) -> 20 | AN8: =COUNTIF($C8:$W8,H8) -> 20 | AO8: =COUNTIF($C8:$W8,T8) -> 20 | AP8: =COUNTIF($C8:$W8,U8) -> 1 | AQ8: =COUNTIF($C8:$W8,V8) -> 20 | AR8: =COUNTIF($C8:$W8,W8) -> 20
A9: Machtday 1 | B9: Arsenal | C9: =VLOOKUP($C$2,Form_PrimeiraFase!$C$2:$FB$69,3,FALSE) -> Arsenal | D9: =VLOOKUP($D$2,Form_PrimeiraFase!$C$2:$FB$69,3,FALSE) -> Arsenal | E9: =VLOOKUP($E$2,Form_PrimeiraFase!$C$2:$FB$69,3,FALSE) -> Arsenal | F9: =VLOOKUP($F$2,Form_PrimeiraFase!$C$2:$FB$69,3,FALSE) -> Arsenal | G9: =VLOOKUP($G$2,Form_PrimeiraFase!$C$2:$FB$69,3,FALSE) -> Arsenal | H9: =VLOOKUP($H$2,Form_PrimeiraFase!$C$2:$FB$69,3,FALSE) -> Arsenal | I9: =VLOOKUP($I$2,Form_PrimeiraFase!$C$2:$FB$69,3,FALSE) -> Arsenal | J9: =VLOOKUP($J$2,Form_PrimeiraFase!$C$2:$FB$69,3,FALSE) -> Arsenal | K9: =VLOOKUP($K$2,Form_PrimeiraFase!$C$2:$FB$69,3,FALSE) -> Arsenal | L9: =VLOOKUP($L$2,Form_PrimeiraFase!$C$2:$FB$69,3,FALSE) -> Arsenal | M9: =VLOOKUP($M$2,Form_PrimeiraFase!$C$2:$FB$69,3,FALSE) -> Arsenal | N9: =VLOOKUP($N$2,Form_PrimeiraFase!$C$2:$FB$69,3,FALSE) -> Arsenal | O9: =VLOOKUP($O$2,Form_PrimeiraFase!$C$2:$FB$69,3,FALSE) -> Arsenal | P9: =VLOOKUP($P$2,Form_PrimeiraFase!$C$2:$FB$69,3,FALSE) -> Empate | Q9: =VLOOKUP($Q$2,Form_PrimeiraFase!$C$2:$FB$69,3,FALSE) -> Arsenal | R9: =VLOOKUP($R$2,Form_PrimeiraFase!$C$2:$FB$69,3,FALSE) -> Arsenal | S9: =VLOOKUP($S$2,Form_PrimeiraFase!$C$2:$FB$69,3,FALSE) -> Arsenal | T9: =VLOOKUP($T$2,Form_PrimeiraFase!$C$2:$FB$69,3,FALSE) -> Arsenal | U9: =VLOOKUP($U$2,Form_PrimeiraFase!$C$2:$FB$69,3,FALSE) -> Empate | V9: =VLOOKUP($V$2,Form_PrimeiraFase!$C$2:$FB$69,3,FALSE) -> Arsenal | W9: =VLOOKUP($W$2,Form_PrimeiraFase!$C$2:$FB$69,3,FALSE) -> Arsenal | X9: =COUNTIF($C9:$W9,J9) -> 19 | Y9: =COUNTIF($C9:$W9,K9) -> 19 | Z9: =COUNTIF($C9:$W9,R9) -> 19 | AA9: =COUNTIF($C9:$W9,D9) -> 19 | AB9: =COUNTIF($C9:$W9,N9) -> 19 | AC9: =COUNTIF($C9:$W9,O9) -> 19 | AD9: =COUNTIF($C9:$W9,G9) -> 19 | AE9: =COUNTIF($C9:$W9,F9) -> 19 | AF9: =COUNTIF($C9:$W9,E9) -> 19 | AG9: =COUNTIF($C9:$W9,S9) -> 19 | AH9: =COUNTIF($C9:$W9,C9) -> 19 | AI9: =COUNTIF($C9:$W9,P9) -> 2 | AJ9: =COUNTIF($C9:$W9,M9) -> 19 | AK9: =COUNTIF($C9:$W9,I9) -> 19 | AL9: =COUNTIF($C9:$W9,Q9) -> 19 | AM9: =COUNTIF($C9:$W9,L9) -> 19 | AN9: =COUNTIF($C9:$W9,H9) -> 19 | AO9: =COUNTIF($C9:$W9,T9) -> 19 | AP9: =COUNTIF($C9:$W9,U9) -> 2 | AQ9: =COUNTIF($C9:$W9,V9) -> 19 | AR9: =COUNTIF($C9:$W9,W9) -> 19
A10: Machtday 1 | B10: Real Madrid | C10: =VLOOKUP($C$2,Form_PrimeiraFase!$C$2:$FB$69,4,FALSE) -> Real Madrid | D10: =VLOOKUP($D$2,Form_PrimeiraFase!$C$2:$FB$69,4,FALSE) -> Real Madrid | E10: =VLOOKUP($E$2,Form_PrimeiraFase!$C$2:$FB$69,4,FALSE) -> Real Madrid | F10: =VLOOKUP($F$2,Form_PrimeiraFase!$C$2:$FB$69,4,FALSE) -> Real Madrid | G10: =VLOOKUP($G$2,Form_PrimeiraFase!$C$2:$FB$69,4,FALSE) -> Real Madrid | H10: =VLOOKUP($H$2,Form_PrimeiraFase!$C$2:$FB$69,4,FALSE) -> Real Madrid | I10: =VLOOKUP($I$2,Form_PrimeiraFase!$C$2:$FB$69,4,FALSE) -> Real Madrid | J10: =VLOOKUP($J$2,Form_PrimeiraFase!$C$2:$FB$69,4,FALSE) -> Real Madrid | K10: =VLOOKUP($K$2,Form_PrimeiraFase!$C$2:$FB$69,4,FALSE) -> Real Madrid | L10: =VLOOKUP($L$2,Form_PrimeiraFase!$C$2:$FB$69,4,FALSE) -> Real Madrid | M10: =VLOOKUP($M$2,Form_PrimeiraFase!$C$2:$FB$69,4,FALSE) -> Real Madrid | N10: =VLOOKUP($N$2,Form_PrimeiraFase!$C$2:$FB$69,4,FALSE) -> Real Madrid | O10: =VLOOKUP($O$2,Form_PrimeiraFase!$C$2:$FB$69,4,FALSE) -> Real Madrid | P10: =VLOOKUP($P$2,Form_PrimeiraFase!$C$2:$FB$69,4,FALSE) -> Real Madrid | Q10: =VLOOKUP($Q$2,Form_PrimeiraFase!$C$2:$FB$69,4,FALSE) -> Real Madrid | R10: =VLOOKUP($R$2,Form_PrimeiraFase!$C$2:$FB$69,4,FALSE) -> Real Madrid | S10: =VLOOKUP($S$2,Form_PrimeiraFase!$C$2:$FB$69,4,FALSE) -> Real Madrid | T10: =VLOOKUP($T$2,Form_PrimeiraFase!$C$2:$FB$69,4,FALSE) -> Real Madrid | U10: =VLOOKUP($U$2,Form_PrimeiraFase!$C$2:$FB$69,4,FALSE) -> Real Madrid | V10: =VLOOKUP($V$2,Form_PrimeiraFase!$C$2:$FB$69,4,FALSE) -> Real Madrid | W10: =VLOOKUP($W$2,Form_PrimeiraFase!$C$2:$FB$69,4,FALSE) -> Real Madrid | X10: =COUNTIF($C10:$W10,J10) -> 21 | Y10: =COUNTIF($C10:$W10,K10) -> 21 | Z10: =COUNTIF($C10:$W10,R10) -> 21 | AA10: =COUNTIF($C10:$W10,D10) -> 21 | AB10: =COUNTIF($C10:$W10,N10) -> 21 | AC10: =COUNTIF($C10:$W10,O10) -> 21 | AD10: =COUNTIF($C10:$W10,G10) -> 21 | AE10: =COUNTIF($C10:$W10,F10) -> 21 | AF10: =COUNTIF($C10:$W10,E10) -> 21 | AG10: =COUNTIF($C10:$W10,S10) -> 21 | AH10: =COUNTIF($C10:$W10,C10) -> 21 | AI10: =COUNTIF($C10:$W10,P10) -> 21 | AJ10: =COUNTIF($C10:$W10,M10) -> 21 | AK10: =COUNTIF($C10:$W10,I10) -> 21 | AL10: =COUNTIF($C10:$W10,Q10) -> 21 | AM10: =COUNTIF($C10:$W10,L10) -> 21 | AN10: =COUNTIF($C10:$W10,H10) -> 21 | AO10: =COUNTIF($C10:$W10,T10) -> 21 | AP10: =COUNTIF($C10:$W10,U10) -> 21 | AQ10: =COUNTIF($C10:$W10,V10) -> 21 | AR10: =COUNTIF($C10:$W10,W10) -> 21
A11: Machtday 1 | B11: Qarabag | C11: =VLOOKUP($C$2,Form_PrimeiraFase!$C$2:$FB$69,5,FALSE) -> Benfica | D11: =VLOOKUP($D$2,Form_PrimeiraFase!$C$2:$FB$69,5,FALSE) -> Benfica | E11: =VLOOKUP($E$2,Form_PrimeiraFase!$C$2:$FB$69,5,FALSE) -> Benfica | F11: =VLOOKUP($F$2,Form_PrimeiraFase!$C$2:$FB$69,5,FALSE) -> Benfica | G11: =VLOOKUP($G$2,Form_PrimeiraFase!$C$2:$FB$69,5,FALSE) -> Benfica | H11: =VLOOKUP($H$2,Form_PrimeiraFase!$C$2:$FB$69,5,FALSE) -> Benfica | I11: =VLOOKUP($I$2,Form_PrimeiraFase!$C$2:$FB$69,5,FALSE) -> Benfica | J11: =VLOOKUP($J$2,Form_PrimeiraFase!$C$2:$FB$69,5,FALSE) -> Benfica | K11: =VLOOKUP($K$2,Form_PrimeiraFase!$C$2:$FB$69,5,FALSE) -> Benfica | L11: =VLOOKUP($L$2,Form_PrimeiraFase!$C$2:$FB$69,5,FALSE) -> Benfica | M11: =VLOOKUP($M$2,Form_PrimeiraFase!$C$2:$FB$69,5,FALSE) -> Benfica | N11: =VLOOKUP($N$2,Form_PrimeiraFase!$C$2:$FB$69,5,FALSE) -> Benfica | O11: =VLOOKUP($O$2,Form_PrimeiraFase!$C$2:$FB$69,5,FALSE) -> Benfica | P11: =VLOOKUP($P$2,Form_PrimeiraFase!$C$2:$FB$69,5,FALSE) -> Benfica | Q11: =VLOOKUP($Q$2,Form_PrimeiraFase!$C$2:$FB$69,5,FALSE) -> Benfica | R11: =VLOOKUP($R$2,Form_PrimeiraFase!$C$2:$FB$69,5,FALSE) -> Benfica | S11: =VLOOKUP($S$2,Form_PrimeiraFase!$C$2:$FB$69,5,FALSE) -> Benfica | T11: =VLOOKUP($T$2,Form_PrimeiraFase!$C$2:$FB$69,5,FALSE) -> Benfica | U11: =VLOOKUP($U$2,Form_PrimeiraFase!$C$2:$FB$69,5,FALSE) -> Benfica | V11: =VLOOKUP($V$2,Form_PrimeiraFase!$C$2:$FB$69,5,FALSE) -> Benfica | W11: =VLOOKUP($W$2,Form_PrimeiraFase!$C$2:$FB$69,5,FALSE) -> Benfica | X11: =COUNTIF($C11:$W11,J11) -> 21 | Y11: =COUNTIF($C11:$W11,K11) -> 21 | Z11: =COUNTIF($C11:$W11,R11) -> 21 | AA11: =COUNTIF($C11:$W11,D11) -> 21 | AB11: =COUNTIF($C11:$W11,N11) -> 21 | AC11: =COUNTIF($C11:$W11,O11) -> 21 | AD11: =COUNTIF($C11:$W11,G11) -> 21 | AE11: =COUNTIF($C11:$W11,F11) -> 21 | AF11: =COUNTIF($C11:$W11,E11) -> 21 | AG11: =COUNTIF($C11:$W11,S11) -> 21 | AH11: =COUNTIF($C11:$W11,C11) -> 21 | AI11: =COUNTIF($C11:$W11,P11) -> 21 | AJ11: =COUNTIF($C11:$W11,M11) -> 21 | AK11: =COUNTIF($C11:$W11,I11) -> 21 | AL11: =COUNTIF($C11:$W11,Q11) -> 21 | AM11: =COUNTIF($C11:$W11,L11) -> 21 | AN11: =COUNTIF($C11:$W11,H11) -> 21 | AO11: =COUNTIF($C11:$W11,T11) -> 21 | AP11: =COUNTIF($C11:$W11,U11) -> 21 | AQ11: =COUNTIF($C11:$W11,V11) -> 21 | AR11: =COUNTIF($C11:$W11,W11) -> 21
